Workbook

Sheet README
B1: LOKAL - META DAY-ON-DAY NETWORK & DEMOGRAPHIC SPLITS (Oct 1-5, 2026)
B3: PURPOSE
B4: Diagnose the Trial CAC increase over Oct 1-5 and test whether it is a uniform account-wide shock (as hypothesised: a step-up around mid-day Saturday Oct 3) or concentrated in specific segments / scaled adsets.
B6: DATA & GRANULARITY
B7: Source: Meta Ads API, account 2078697462372876 (Lokal), pulled 5 Oct. Raw pulls are on the RAW_* tabs; every summary tab is built from them with SUMIFS formulas (nothing is hardcoded).
B8: The API returns DAILY granularity only. Hourly data is not available, so the exact 'around 12pm Saturday' timing cannot be confirmed from ad data. Windows are Before = Oct 1-2 (Thu-Fri) and After = Oct 3-4 (Sat-Sun).
B9: Trial = app_custom_event_fb_mobile_purchase (the Rs 2 trial). Install = mobile_app_install. CPI = spend / installs. Trial CAC = spend / trials. Install-Trial % = trials / installs.
B11: THREE CAVEATS - READ BEFORE DRAWING CONCLUSIONS
B12: 1. ATTRIBUTION LAG. Oct 3-5 trials are still attributing (purchases land over several days). The most recent days therefore read with FEWER trials than they will finally have, so their Trial CAC is OVERSTATED. Oct 1-2 are fully matured; Oct 3 is mostly matured; Oct 4-5 are the least mature.
B13: 2. HEAVY BUDGET SCALING. On Oct 3-4 budgets were scaled up aggressively across ~40 adsets (towards the October plan). A large same-day budget jump resets an adset's learning and temporarily lifts its CAC, independent of any auction or app change.
B14: 3. NO RELEASE NOTES. Unlike the August report, there is no known Play Store release in this window to correlate against. There is therefore no 'Login vs Rollout' tab; that dose-response check needs the internal dashboard and a known build timeline.
B16: WHAT THE DATA SHOWS (stated conservatively)
... B24: DECISIVE CHECKS: (1) re-pull Oct 3-5 in 3-4 days once trials have fully attributed and re-read the daily CAC; (2) if a systemic cause is still suspected, confirm there was no app release and check internal login-success % by app version; (3) hold budgets flat for 48h to let the scaled adsets exit learning, then re-measure.

Sheet Daily Trend (Meta)
A1: Date | B1: Spend (Rs) | C1: CPM | D1: CTR % | E1: Installs | F1: Trials | G1: CPI | H1: Install-Trial % | I1: Trial CAC | J1: Note
A2: Oct 1 | B2: =RAW_Daily!C2 | C2: =RAW_Daily!E2 | D2: =RAW_Daily!F2 | E2: =RAW_Daily!G2 | F2: =RAW_Daily!H2 | G2: =IFERROR(RAW_Daily!C2/RAW_Daily!G2,"-") | H2: =IFERROR(RAW_Daily!H2/RAW_Daily!G2*100,"-") | I2: =IFERROR(RAW_Daily!C2/RAW_Daily!H2,"-")
A3: Oct 2 | B3: =RAW_Daily!C3 | C3: =RAW_Daily!E3 | D3: =RAW_Daily!F3 | E3: =RAW_Daily!G3 | F3: =RAW_Daily!H3 | G3: =IFERROR(RAW_Daily!C3/RAW_Daily!G3,"-") | H3: =IFERROR(RAW_Daily!H3/RAW_Daily!G3*100,"-") | I3: =IFERROR(RAW_Daily!C3/RAW_Daily!H3,"-")
A4: Oct 3 | B4: =RAW_Daily!C4 | C4: =RAW_Daily!E4 | D4: =RAW_Daily!F4 | E4: =RAW_Daily!G4 | F4: =RAW_Daily!H4 | G4: =IFERROR(RAW_Daily!C4/RAW_Daily!G4,"-") | H4: =IFERROR(RAW_Daily!H4/RAW_Daily!G4*100,"-") | I4: =IFERROR(RAW_Daily!C4/RAW_Daily!H4,"-") | J4: Sat - heavy mid-day budget scaling across account
A5: Oct 4 | B5: =RAW_Daily!C5 | C5: =RAW_Daily!E5 | D5: =RAW_Daily!F5 | E5: =RAW_Daily!G5 | F5: =RAW_Daily!H5 | G5: =IFERROR(RAW_Daily!C5/RAW_Daily!G5,"-") | H5: =IFERROR(RAW_Daily!H5/RAW_Daily!G5*100,"-") | I5: =IFERROR(RAW_Daily!C5/RAW_Daily!H5,"-") | J5: Sun - scaling continues
A6: Oct 5 | B6: =RAW_Daily!C6 | C6: =RAW_Daily!E6 | D6: =RAW_Daily!F6 | E6: =RAW_Daily!G6 | F6: =RAW_Daily!H6 | G6: =IFERROR(RAW_Daily!C6/RAW_Daily!G6,"-") | H6: =IFERROR(RAW_Daily!H6/RAW_Daily!G6*100,"-") | I6: =IFERROR(RAW_Daily!C6/RAW_Daily!H6,"-") | J6: Mon - partial day, trials still attributing

Sheet Window Summary
A1: WINDOW SUMMARY - Oct 5 is a partial day and is shown separately, not blended. CAC on Oct 3-5 is understated-trials still attributing.
A2: Window | B2: Spend (Rs) | C2: Days | D2: Avg spend/day | E2: Installs | F2: CPI | G2: Trials | H2: Install-Trial % | I2: Trial CAC
A3: Before: Oct 1-2 (Thu-Fri, pre-Sat) | B3: =SUMIFS(RAW_Daily!$C$2:$C$6,RAW_Daily!$B$2:$B$6,">=1",RAW_Daily!$B$2:$B$6,"<=2") | C3: 2 | D3: =SUMIFS(RAW_Daily!$C$2:$C$6,RAW_Daily!$B$2:$B$6,">=1",RAW_Daily!$B$2:$B$6,"<=2")/2 | E3: =SUMIFS(RAW_Daily!$G$2:$G$6,RAW_Daily!$B$2:$B$6,">=1",RAW_Daily!$B$2:$B$6,"<=2") | F3: =IFERROR(SUMIFS(RAW_Daily!$C$2:$C$6,RAW_Daily!$B$2:$B$6,">=1",RAW_Daily!$B$2:$B$6,"<=2")/SUMIFS(RAW_Daily!$G$2:$G$6,RAW_Daily!$B$2:$B$6,">=1",RAW_Daily!$B$2:$B$6,"<=2"),"-") | G3: =SUMIFS(RAW_Daily!$H$2:$H$6,RAW_Daily!$B$2:$B$6,">=1",RAW_Daily!$B$2:$B$6,"<=2") | H3: =IFERROR(SUMIFS(RAW_Daily!$H$2:$H$6,RAW_Daily!$B$2:$B$6,">=1",RAW_Daily!$B$2:$B$6,"<=2")/SUMIFS(RAW_Daily!$G$2:$G$6,RAW_Daily!$B$2:$B$6,">=1",RAW_Daily!$B$2:$B$6,"<=2")*100,"-") | I3: =IFERROR(SUMIFS(RAW_Daily!$C$2:$C$6,RAW_Daily!$B$2:$B$6,">=1",RAW_Daily!$B$2:$B$6,"<=2")/SUMIFS(RAW_Daily!$H$2:$H$6,RAW_Daily!$B$2:$B$6,">=1",RAW_Daily!$B$2:$B$6,"<=2"),"-")
A4: After: Oct 3-4 (Sat-Sun) | B4: =SUMIFS(RAW_Daily!$C$2:$C$6,RAW_Daily!$B$2:$B$6,">=3",RAW_Daily!$B$2:$B$6,"<=4") | C4: 2 | D4: =SUMIFS(RAW_Daily!$C$2:$C$6,RAW_Daily!$B$2:$B$6,">=3",RAW_Daily!$B$2:$B$6,"<=4")/2 | E4: =SUMIFS(RAW_Daily!$G$2:$G$6,RAW_Daily!$B$2:$B$6,">=3",RAW_Daily!$B$2:$B$6,"<=4") | F4: =IFERROR(SUMIFS(RAW_Daily!$C$2:$C$6,RAW_Daily!$B$2:$B$6,">=3",RAW_Daily!$B$2:$B$6,"<=4")/SUMIFS(RAW_Daily!$G$2:$G$6,RAW_Daily!$B$2:$B$6,">=3",RAW_Daily!$B$2:$B$6,"<=4"),"-") | G4: =SUMIFS(RAW_Daily!$H$2:$H$6,RAW_Daily!$B$2:$B$6,">=3",RAW_Daily!$B$2:$B$6,"<=4") | H4: =IFERROR(SUMIFS(RAW_Daily!$H$2:$H$6,RAW_Daily!$B$2:$B$6,">=3",RAW_Daily!$B$2:$B$6,"<=4")/SUMIFS(RAW_Daily!$G$2:$G$6,RAW_Daily!$B$2:$B$6,">=3",RAW_Daily!$B$2:$B$6,"<=4")*100,"-") | I4: =IFERROR(SUMIFS(RAW_Daily!$C$2:$C$6,RAW_Daily!$B$2:$B$6,">=3",RAW_Daily!$B$2:$B$6,"<=4")/SUMIFS(RAW_Daily!$H$2:$H$6,RAW_Daily!$B$2:$B$6,">=3",RAW_Daily!$B$2:$B$6,"<=4"),"-")
A5: Oct 5 (Mon, partial day) | B5: =SUMIFS(RAW_Daily!$C$2:$C$6,RAW_Daily!$B$2:$B$6,">=5",RAW_Daily!$B$2:$B$6,"<=5") | C5: 1 | D5: =SUMIFS(RAW_Daily!$C$2:$C$6,RAW_Daily!$B$2:$B$6,">=5",RAW_Daily!$B$2:$B$6,"<=5")/1 | E5: =SUMIFS(RAW_Daily!$G$2:$G$6,RAW_Daily!$B$2:$B$6,">=5",RAW_Daily!$B$2:$B$6,"<=5") | F5: =IFERROR(SUMIFS(RAW_Daily!$C$2:$C$6,RAW_Daily!$B$2:$B$6,">=5",RAW_Daily!$B$2:$B$6,"<=5")/SUMIFS(RAW_Daily!$G$2:$G$6,RAW_Daily!$B$2:$B$6,">=5",RAW_Daily!$B$2:$B$6,"<=5"),"-") | G5: =SUMIFS(RAW_Daily!$H$2:$H$6,RAW_Daily!$B$2:$B$6,">=5",RAW_Daily!$B$2:$B$6,"<=5") | H5: =IFERROR(SUMIFS(RAW_Daily!$H$2:$H$6,RAW_Daily!$B$2:$B$6,">=5",RAW_Daily!$B$2:$B$6,"<=5")/SUMIFS(RAW_Daily!$G$2:$G$6,RAW_Daily!$B$2:$B$6,">=5",RAW_Daily!$B$2:$B$6,"<=5")*100,"-") | I5: =IFERROR(SUMIFS(RAW_Daily!$C$2:$C$6,RAW_Daily!$B$2:$B$6,">=5",RAW_Daily!$B$2:$B$6,"<=5")/SUMIFS(RAW_Daily!$H$2:$H$6,RAW_Daily!$B$2:$B$6,">=5",RAW_Daily!$B$2:$B$6,"<=5"),"-")

Sheet Network Split
A1: NETWORK (PUBLISHER PLATFORM) SPLIT - share of spend/installs/trials + CPI + Trial CAC, per window. If CAC rose on both FB and IG together it is uniform, not a network shift.
A2: Window | B2: Segment | C2: Spend (Rs) | D2: Spend % | E2: Installs | F2: Install % | G2: Trials | H2: CPI | I2: Trial CAC | J2: Inflation
A3: Before Oct 1-2 | B3: Facebook | C3: =SUMIFS(RAW_Network!$D$2:$D$21,RAW_Network!$B$2:$B$21,">=1",RAW_Network!$B$2:$B$21,"<=2",RAW_Network!$C$2:$C$21,"Facebook") | D3: =IFERROR(SUMIFS(RAW_Network!$D$2:$D$21,RAW_Network!$B$2:$B$21,">=1",RAW_Network!$B$2:$B$21,"<=2",RAW_Network!$C$2:$C$21,"Facebook")/SUMIFS(RAW_Network!$D$2:$D$21,RAW_Network!$B$2:$B$21,">=1",RAW_Network!$B$2:$B$21,"<=2")*100,"-") | E3: =SUMIFS(RAW_Network!$E$2:$E$21,RAW_Network!$B$2:$B$21,">=1",RAW_Network!$B$2:$B$21,"<=2",RAW_Network!$C$2:$C$21,"Facebook") | F3: =IFERROR(SUMIFS(RAW_Network!$E$2:$E$21,RAW_Network!$B$2:$B$21,">=1",RAW_Network!$B$2:$B$21,"<=2",RAW_Network!$C$2:$C$21,"Facebook")/SUMIFS(RAW_Network!$E$2:$E$21,RAW_Network!$B$2:$B$21,">=1",RAW_Network!$B$2:$B$21,"<=2")*100,"-") | G3: =SUMIFS(RAW_Network!$F$2:$F$21,RAW_Network!$B$2:$B$21,">=1",RAW_Network!$B$2:$B$21,"<=2",RAW_Network!$C$2:$C$21,"Facebook") | H3: =IFERROR(SUMIFS(RAW_Network!$D$2:$D$21,RAW_Network!$B$2:$B$21,">=1",RAW_Network!$B$2:$B$21,"<=2",RAW_Network!$C$2:$C$21,"Facebook")/SUMIFS(RAW_Network!$E$2:$E$21,RAW_Network!$B$2:$B$21,">=1",RAW_Network!$B$2:$B$21,"<=2",RAW_Network!$C$2:$C$21,"Facebook"),"-") | I3: =IFERROR(SUMIFS(RAW_Network!$D$2:$D$21,RAW_Network!$B$2:$B$21,">=1",RAW_Network!$B$2:$B$21,"<=2",RAW_Network!$C$2:$C$21,"Facebook")/SUMIFS(RAW_Network!$F$2:$F$21,RAW_Network!$B$2:$B$21,">=1",RAW_Network!$B$2:$B$21,"<=2",RAW_Network!$C$2:$C$21,"Facebook"),"-")
B4: Instagram | C4: =SUMIFS(RAW_Network!$D$2:$D$21,RAW_Network!$B$2:$B$21,">=1",RAW_Network!$B$2:$B$21,"<=2",RAW_Network!$C$2:$C$21,"Instagram") | D4: =IFERROR(SUMIFS(RAW_Network!$D$2:$D$21,RAW_Network!$B$2:$B$21,">=1",RAW_Network!$B$2:$B$21,"<=2",RAW_Network!$C$2:$C$21,"Instagram")/SUMIFS(RAW_Network!$D$2:$D$21,RAW_Network!$B$2:$B$21,">=1",RAW_Network!$B$2:$B$21,"<=2")*100,"-") | E4: =SUMIFS(RAW_Network!$E$2:$E$21,RAW_Network!$B$2:$B$21,">=1",RAW_Network!$B$2:$B$21,"<=2",RAW_Network!$C$2:$C$21,"Instagram") | F4: =IFERROR(SUMIFS(RAW_Network!$E$2:$E$21,RAW_Network!$B$2:$B$21,">=1",RAW_Network!$B$2:$B$21,"<=2",RAW_Network!$C$2:$C$21,"Instagram")/SUMIFS(RAW_Network!$E$2:$E$21,RAW_Network!$B$2:$B$21,">=1",RAW_Network!$B$2:$B$21,"<=2")*100,"-") | G4: =SUMIFS(RAW_Network!$F$2:$F$21,RAW_Network!$B$2:$B$21,">=1",RAW_Network!$B$2:$B$21,"<=2",RAW_Network!$C$2:$C$21,"Instagram") | H4: =IFERROR(SUMIFS(RAW_Network!$D$2:$D$21,RAW_Network!$B$2:$B$21,">=1",RAW_Network!$B$2:$B$21,"<=2",RAW_Network!$C$2:$C$21,"Instagram")/SUMIFS(RAW_Network!$E$2:$E$21,RAW_Network!$B$2:$B$21,">=1",RAW_Network!$B$2:$B$21,"<=2",RAW_Network!$C$2:$C$21,"Instagram"),"-") | I4: =IFERROR(SUMIFS(RAW_Network!$D$2:$D$21,RAW_Network!$B$2:$B$21,">=1",RAW_Network!$B$2:$B$21,"<=2",RAW_Network!$C$2:$C$21,"Instagram")/SUMIFS(RAW_Network!$F$2:$F$21,RAW_Network!$B$2:$B$21,">=1",RAW_Network!$B$2:$B$21,"<=2",RAW_Network!$C$2:$C$21,"Instagram"),"-")
B5: Audience Network | C5: =SUMIFS(RAW_Network!$D$2:$D$21,RAW_Network!$B$2:$B$21,">=1",RAW_Network!$B$2:$B$21,"<=2",RAW_Network!$C$2:$C$21,"Audience Network") | D5: =IFERROR(SUMIFS(RAW_Network!$D$2:$D$21,RAW_Network!$B$2:$B$21,">=1",RAW_Network!$B$2:$B$21,"<=2",RAW_Network!$C$2:$C$21,"Audience Network")/SUMIFS(RAW_Network!$D$2:$D$21,RAW_Network!$B$2:$B$21,">=1",RAW_Network!$B$2:$B$21,"<=2")*100,"-") | E5: =SUMIFS(RAW_Network!$E$2:$E$21,RAW_Network!$B$2:$B$21,">=1",RAW_Network!$B$2:$B$21,"<=2",RAW_Network!$C$2:$C$21,"Audience Network") | F5: =IFERROR(SUMIFS(RAW_Network!$E$2:$E$21,RAW_Network!$B$2:$B$21,">=1",RAW_Network!$B$2:$B$21,"<=2",RAW_Network!$C$2:$C$21,"Audience Network")/SUMIFS(RAW_Network!$E$2:$E$21,RAW_Network!$B$2:$B$21,">=1",RAW_Network!$B$2:$B$21,"<=2")*100,"-") | G5: =SUMIFS(RAW_Network!$F$2:$F$21,RAW_Network!$B$2:$B$21,">=1",RAW_Network!$B$2:$B$21,"<=2",RAW_Network!$C$2:$C$21,"Audience Network") | H5: =IFERROR(SUMIFS(RAW_Network!$D$2:$D$21,RAW_Network!$B$2:$B$21,">=1",RAW_Network!$B$2:$B$21,"<=2",RAW_Network!$C$2:$C$21,"Audience Network")/SUMIFS(RAW_Network!$E$2:$E$21,RAW_Network!$B$2:$B$21,">=1",RAW_Network!$B$2:$B$21,"<=2",RAW_Network!$C$2:$C$21,"Audience Network"),"-") | I5: =IFERROR(SUMIFS(RAW_Network!$D$2:$D$21,RAW_Network!$B$2:$B$21,">=1",RAW_Network!$B$2:$B$21,"<=2",RAW_Network!$C$2:$C$21,"Audience Network")/SUMIFS(RAW_Network!$F$2:$F$21,RAW_Network!$B$2:$B$21,">=1",RAW_Network!$B$2:$B$21,"<=2",RAW_Network!$C$2:$C$21,"Audience Network"),"-")
B6: Threads | C6: =SUMIFS(RAW_Network!$D$2:$D$21,RAW_Network!$B$2:$B$21,">=1",RAW_Network!$B$2:$B$21,"<=2",RAW_Network!$C$2:$C$21,"Threads") | D6: =IFERROR(SUMIFS(RAW_Network!$D$2:$D$21,RAW_Network!$B$2:$B$21,">=1",RAW_Network!$B$2:$B$21,"<=2",RAW_Network!$C$2:$C$21,"Threads")/SUMIFS(RAW_Network!$D$2:$D$21,RAW_Network!$B$2:$B$21,">=1",RAW_Network!$B$2:$B$21,"<=2")*100,"-") | E6: =SUMIFS(RAW_Network!$E$2:$E$21,RAW_Network!$B$2:$B$21,">=1",RAW_Network!$B$2:$B$21,"<=2",RAW_Network!$C$2:$C$21,"Threads") | F6: =IFERROR(SUMIFS(RAW_Network!$E$2:$E$21,RAW_Network!$B$2:$B$21,">=1",RAW_Network!$B$2:$B$21,"<=2",RAW_Network!$C$2:$C$21,"Threads")/SUMIFS(RAW_Network!$E$2:$E$21,RAW_Network!$B$2:$B$21,">=1",RAW_Network!$B$2:$B$21,"<=2")*100,"-") | G6: =SUMIFS(RAW_Network!$F$2:$F$21,RAW_Network!$B$2:$B$21,">=1",RAW_Network!$B$2:$B$21,"<=2",RAW_Network!$C$2:$C$21,"Threads") | H6: =IFERROR(SUMIFS(RAW_Network!$D$2:$D$21,RAW_Network!$B$2:$B$21,">=1",RAW_Network!$B$2:$B$21,"<=2",RAW_Network!$C$2:$C$21,"Threads")/SUMIFS(RAW_Network!$E$2:$E$21,RAW_Network!$B$2:$B$21,">=1",RAW_Network!$B$2:$B$21,"<=2",RAW_Network!$C$2:$C$21,"Threads"),"-") | I6: =IFERROR(SUMIFS(RAW_Network!$D$2:$D$21,RAW_Network!$B$2:$B$21,">=1",RAW_Network!$B$2:$B$21,"<=2",RAW_Network!$C$2:$C$21,"Threads")/SUMIFS(RAW_Network!$F$2:$F$21,RAW_Network!$B$2:$B$21,">=1",RAW_Network!$B$2:$B$21,"<=2",RAW_Network!$C$2:$C$21,"Threads"),"-")
A7: After Oct 3-4 | B7: Facebook | C7: =SUMIFS(RAW_Network!$D$2:$D$21,RAW_Network!$B$2:$B$21,">=3",RAW_Network!$B$2:$B$21,"<=4",RAW_Network!$C$2:$C$21,"Facebook") | D7: =IFERROR(SUMIFS(RAW_Network!$D$2:$D$21,RAW_Network!$B$2:$B$21,">=3",RAW_Network!$B$2:$B$21,"<=4",RAW_Network!$C$2:$C$21,"Facebook")/SUMIFS(RAW_Network!$D$2:$D$21,RAW_Network!$B$2:$B$21,">=3",RAW_Network!$B$2:$B$21,"<=4")*100,"-") | E7: =SUMIFS(RAW_Network!$E$2:$E$21,RAW_Network!$B$2:$B$21,">=3",RAW_Network!$B$2:$B$21,"<=4",RAW_Network!$C$2:$C$21,"Facebook") | F7: =IFERROR(SUMIFS(RAW_Network!$E$2:$E$21,RAW_Network!$B$2:$B$21,">=3",RAW_Network!$B$2:$B$21,"<=4",RAW_Network!$C$2:$C$21,"Facebook")/SUMIFS(RAW_Network!$E$2:$E$21,RAW_Network!$B$2:$B$21,">=3",RAW_Network!$B$2:$B$21,"<=4")*100,"-") | G7: =SUMIFS(RAW_Network!$F$2:$F$21,RAW_Network!$B$2:$B$21,">=3",RAW_Network!$B$2:$B$21,"<=4",RAW_Network!$C$2:$C$21,"Facebook") | H7: =IFERROR(SUMIFS(RAW_Network!$D$2:$D$21,RAW_Network!$B$2:$B$21,">=3",RAW_Network!$B$2:$B$21,"<=4",RAW_Network!$C$2:$C$21,"Facebook")/SUMIFS(RAW_Network!$E$2:$E$21,RAW_Network!$B$2:$B$21,">=3",RAW_Network!$B$2:$B$21,"<=4",RAW_Network!$C$2:$C$21,"Facebook"),"-") | I7: =IFERROR(SUMIFS(RAW_Network!$D$2:$D$21,RAW_Network!$B$2:$B$21,">=3",RAW_Network!$B$2:$B$21,"<=4",RAW_Network!$C$2:$C$21,"Facebook")/SUMIFS(RAW_Network!$F$2:$F$21,RAW_Network!$B$2:$B$21,">=3",RAW_Network!$B$2:$B$21,"<=4",RAW_Network!$C$2:$C$21,"Facebook"),"-") | J7: =IFERROR(H7/H3,"-")
B8: Instagram | C8: =SUMIFS(RAW_Network!$D$2:$D$21,RAW_Network!$B$2:$B$21,">=3",RAW_Network!$B$2:$B$21,"<=4",RAW_Network!$C$2:$C$21,"Instagram") | D8: =IFERROR(SUMIFS(RAW_Network!$D$2:$D$21,RAW_Network!$B$2:$B$21,">=3",RAW_Network!$B$2:$B$21,"<=4",RAW_Network!$C$2:$C$21,"Instagram")/SUMIFS(RAW_Network!$D$2:$D$21,RAW_Network!$B$2:$B$21,">=3",RAW_Network!$B$2:$B$21,"<=4")*100,"-") | E8: =SUMIFS(RAW_Network!$E$2:$E$21,RAW_Network!$B$2:$B$21,">=3",RAW_Network!$B$2:$B$21,"<=4",RAW_Network!$C$2:$C$21,"Instagram") | F8: =IFERROR(SUMIFS(RAW_Network!$E$2:$E$21,RAW_Network!$B$2:$B$21,">=3",RAW_Network!$B$2:$B$21,"<=4",RAW_Network!$C$2:$C$21,"Instagram")/SUMIFS(RAW_Network!$E$2:$E$21,RAW_Network!$B$2:$B$21,">=3",RAW_Network!$B$2:$B$21,"<=4")*100,"-") | G8: =SUMIFS(RAW_Network!$F$2:$F$21,RAW_Network!$B$2:$B$21,">=3",RAW_Network!$B$2:$B$21,"<=4",RAW_Network!$C$2:$C$21,"Instagram") | H8: =IFERROR(SUMIFS(RAW_Network!$D$2:$D$21,RAW_Network!$B$2:$B$21,">=3",RAW_Network!$B$2:$B$21,"<=4",RAW_Network!$C$2:$C$21,"Instagram")/SUMIFS(RAW_Network!$E$2:$E$21,RAW_Network!$B$2:$B$21,">=3",RAW_Network!$B$2:$B$21,"<=4",RAW_Network!$C$2:$C$21,"Instagram"),"-") | I8: =IFERROR(SUMIFS(RAW_Network!$D$2:$D$21,RAW_Network!$B$2:$B$21,">=3",RAW_Network!$B$2:$B$21,"<=4",RAW_Network!$C$2:$C$21,"Instagram")/SUMIFS(RAW_Network!$F$2:$F$21,RAW_Network!$B$2:$B$21,">=3",RAW_Network!$B$2:$B$21,"<=4",RAW_Network!$C$2:$C$21,"Instagram"),"-") | J8: =IFERROR(H8/H4,"-")
B9: Audience Network | C9: =SUMIFS(RAW_Network!$D$2:$D$21,RAW_Network!$B$2:$B$21,">=3",RAW_Network!$B$2:$B$21,"<=4",RAW_Network!$C$2:$C$21,"Audience Network") | D9: =IFERROR(SUMIFS(RAW_Network!$D$2:$D$21,RAW_Network!$B$2:$B$21,">=3",RAW_Network!$B$2:$B$21,"<=4",RAW_Network!$C$2:$C$21,"Audience Network")/SUMIFS(RAW_Network!$D$2:$D$21,RAW_Network!$B$2:$B$21,">=3",RAW_Network!$B$2:$B$21,"<=4")*100,"-") | E9: =SUMIFS(RAW_Network!$E$2:$E$21,RAW_Network!$B$2:$B$21,">=3",RAW_Network!$B$2:$B$21,"<=4",RAW_Network!$C$2:$C$21,"Audience Network") | F9: =IFERROR(SUMIFS(RAW_Network!$E$2:$E$21,RAW_Network!$B$2:$B$21,">=3",RAW_Network!$B$2:$B$21,"<=4",RAW_Network!$C$2:$C$21,"Audience Network")/SUMIFS(RAW_Network!$E$2:$E$21,RAW_Network!$B$2:$B$21,">=3",RAW_Network!$B$2:$B$21,"<=4")*100,"-") | G9: =SUMIFS(RAW_Network!$F$2:$F$21,RAW_Network!$B$2:$B$21,">=3",RAW_Network!$B$2:$B$21,"<=4",RAW_Network!$C$2:$C$21,"Audience Network") | H9: =IFERROR(SUMIFS(RAW_Network!$D$2:$D$21,RAW_Network!$B$2:$B$21,">=3",RAW_Network!$B$2:$B$21,"<=4",RAW_Network!$C$2:$C$21,"Audience Network")/SUMIFS(RAW_Network!$E$2:$E$21,RAW_Network!$B$2:$B$21,">=3",RAW_Network!$B$2:$B$21,"<=4",RAW_Network!$C$2:$C$21,"Audience Network"),"-") | I9: =IFERROR(SUMIFS(RAW_Network!$D$2:$D$21,RAW_Network!$B$2:$B$21,">=3",RAW_Network!$B$2:$B$21,"<=4",RAW_Network!$C$2:$C$21,"Audience Network")/SUMIFS(RAW_Network!$F$2:$F$21,RAW_Network!$B$2:$B$21,">=3",RAW_Network!$B$2:$B$21,"<=4",RAW_Network!$C$2:$C$21,"Audience Network"),"-") | J9: =IFERROR(H9/H5,"-")
B10: Threads | C10: =SUMIFS(RAW_Network!$D$2:$D$21,RAW_Network!$B$2:$B$21,">=3",RAW_Network!$B$2:$B$21,"<=4",RAW_Network!$C$2:$C$21,"Threads") | D10: =IFERROR(SUMIFS(RAW_Network!$D$2:$D$21,RAW_Network!$B$2:$B$21,">=3",RAW_Network!$B$2:$B$21,"<=4",RAW_Network!$C$2:$C$21,"Threads")/SUMIFS(RAW_Network!$D$2:$D$21,RAW_Network!$B$2:$B$21,">=3",RAW_Network!$B$2:$B$21,"<=4")*100,"-") | E10: =SUMIFS(RAW_Network!$E$2:$E$21,RAW_Network!$B$2:$B$21,">=3",RAW_Network!$B$2:$B$21,"<=4",RAW_Network!$C$2:$C$21,"Threads") | F10: =IFERROR(SUMIFS(RAW_Network!$E$2:$E$21,RAW_Network!$B$2:$B$21,">=3",RAW_Network!$B$2:$B$21,"<=4",RAW_Network!$C$2:$C$21,"Threads")/SUMIFS(RAW_Network!$E$2:$E$21,RAW_Network!$B$2:$B$21,">=3",RAW_Network!$B$2:$B$21,"<=4")*100,"-") | G10: =SUMIFS(RAW_Network!$F$2:$F$21,RAW_Network!$B$2:$B$21,">=3",RAW_Network!$B$2:$B$21,"<=4",RAW_Network!$C$2:$C$21,"Threads") | H10: =IFERROR(SUMIFS(RAW_Network!$D$2:$D$21,RAW_Network!$B$2:$B$21,">=3",RAW_Network!$B$2:$B$21,"<=4",RAW_Network!$C$2:$C$21,"Threads")/SUMIFS(RAW_Network!$E$2:$E$21,RAW_Network!$B$2:$B$21,">=3",RAW_Network!$B$2:$B$21,"<=4",RAW_Network!$C$2:$C$21,"Threads"),"-") | I10: =IFERROR(SUMIFS(RAW_Network!$D$2:$D$21,RAW_Network!$B$2:$B$21,">=3",RAW_Network!$B$2:$B$21,"<=4",RAW_Network!$C$2:$C$21,"Threads")/SUMIFS(RAW_Network!$F$2:$F$21,RAW_Network!$B$2:$B$21,">=3",RAW_Network!$B$2:$B$21,"<=4",RAW_Network!$C$2:$C$21,"Threads"),"-") | J10: =IFERROR(H10/H6,"-")

Sheet Daily Network FB vs IG
A1: DAILY NETWORK - Facebook vs Instagram (Oct 1-5). Both rising together = uniform, not a network shift. Oct 3-5 trials still attributing.
A2: Date | B2: FB Spend | C2: FB CPI | D2: FB Trial CAC | E2: FB Trials | F2: IG Spend | G2: IG CPI | H2: IG Trial CAC | I2: IG Trials
A3: Oct 1 | B3: =SUMIFS(RAW_Network!$D$2:$D$21,RAW_Network!$B$2:$B$21,"1",RAW_Network!$C$2:$C$21,"Facebook") | C3: =IFERROR(SUMIFS(RAW_Network!$D$2:$D$21,RAW_Network!$B$2:$B$21,"1",RAW_Network!$C$2:$C$21,"Facebook")/SUMIFS(RAW_Network!$E$2:$E$21,RAW_Network!$B$2:$B$21,"1",RAW_Network!$C$2:$C$21,"Facebook"),"-") | D3: =IFERROR(SUMIFS(RAW_Network!$D$2:$D$21,RAW_Network!$B$2:$B$21,"1",RAW_Network!$C$2:$C$21,"Facebook")/SUMIFS(RAW_Network!$F$2:$F$21,RAW_Network!$B$2:$B$21,"1",RAW_Network!$C$2:$C$21,"Facebook"),"-") | E3: =SUMIFS(RAW_Network!$F$2:$F$21,RAW_Network!$B$2:$B$21,"1",RAW_Network!$C$2:$C$21,"Facebook") | F3: =SUMIFS(RAW_Network!$D$2:$D$21,RAW_Network!$B$2:$B$21,"1",RAW_Network!$C$2:$C$21,"Instagram") | G3: =IFERROR(SUMIFS(RAW_Network!$D$2:$D$21,RAW_Network!$B$2:$B$21,"1",RAW_Network!$C$2:$C$21,"Instagram")/SUMIFS(RAW_Network!$E$2:$E$21,RAW_Network!$B$2:$B$21,"1",RAW_Network!$C$2:$C$21,"Instagram"),"-") | H3: =IFERROR(SUMIFS(RAW_Network!$D$2:$D$21,RAW_Network!$B$2:$B$21,"1",RAW_Network!$C$2:$C$21,"Instagram")/SUMIFS(RAW_Network!$F$2:$F$21,RAW_Network!$B$2:$B$21,"1",RAW_Network!$C$2:$C$21,"Instagram"),"-") | I3: =SUMIFS(RAW_Network!$F$2:$F$21,RAW_Network!$B$2:$B$21,"1",RAW_Network!$C$2:$C$21,"Instagram")
A4: Oct 2 | B4: =SUMIFS(RAW_Network!$D$2:$D$21,RAW_Network!$B$2:$B$21,"2",RAW_Network!$C$2:$C$21,"Facebook") | C4: =IFERROR(SUMIFS(RAW_Network!$D$2:$D$21,RAW_Network!$B$2:$B$21,"2",RAW_Network!$C$2:$C$21,"Facebook")/SUMIFS(RAW_Network!$E$2:$E$21,RAW_Network!$B$2:$B$21,"2",RAW_Network!$C$2:$C$21,"Facebook"),"-") | D4: =IFERROR(SUMIFS(RAW_Network!$D$2:$D$21,RAW_Network!$B$2:$B$21,"2",RAW_Network!$C$2:$C$21,"Facebook")/SUMIFS(RAW_Network!$F$2:$F$21,RAW_Network!$B$2:$B$21,"2",RAW_Network!$C$2:$C$21,"Facebook"),"-") | E4: =SUMIFS(RAW_Network!$F$2:$F$21,RAW_Network!$B$2:$B$21,"2",RAW_Network!$C$2:$C$21,"Facebook") | F4: =SUMIFS(RAW_Network!$D$2:$D$21,RAW_Network!$B$2:$B$21,"2",RAW_Network!$C$2:$C$21,"Instagram") | G4: =IFERROR(SUMIFS(RAW_Network!$D$2:$D$21,RAW_Network!$B$2:$B$21,"2",RAW_Network!$C$2:$C$21,"Instagram")/SUMIFS(RAW_Network!$E$2:$E$21,RAW_Network!$B$2:$B$21,"2",RAW_Network!$C$2:$C$21,"Instagram"),"-") | H4: =IFERROR(SUMIFS(RAW_Network!$D$2:$D$21,RAW_Network!$B$2:$B$21,"2",RAW_Network!$C$2:$C$21,"Instagram")/SUMIFS(RAW_Network!$F$2:$F$21,RAW_Network!$B$2:$B$21,"2",RAW_Network!$C$2:$C$21,"Instagram"),"-") | I4: =SUMIFS(RAW_Network!$F$2:$F$21,RAW_Network!$B$2:$B$21,"2",RAW_Network!$C$2:$C$21,"Instagram")
A5: Oct 3 | B5: =SUMIFS(RAW_Network!$D$2:$D$21,RAW_Network!$B$2:$B$21,"3",RAW_Network!$C$2:$C$21,"Facebook") | C5: =IFERROR(SUMIFS(RAW_Network!$D$2:$D$21,RAW_Network!$B$2:$B$21,"3",RAW_Network!$C$2:$C$21,"Facebook")/SUMIFS(RAW_Network!$E$2:$E$21,RAW_Network!$B$2:$B$21,"3",RAW_Network!$C$2:$C$21,"Facebook"),"-") | D5: =IFERROR(SUMIFS(RAW_Network!$D$2:$D$21,RAW_Network!$B$2:$B$21,"3",RAW_Network!$C$2:$C$21,"Facebook")/SUMIFS(RAW_Network!$F$2:$F$21,RAW_Network!$B$2:$B$21,"3",RAW_Network!$C$2:$C$21,"Facebook"),"-") | E5: =SUMIFS(RAW_Network!$F$2:$F$21,RAW_Network!$B$2:$B$21,"3",RAW_Network!$C$2:$C$21,"Facebook") | F5: =SUMIFS(RAW_Network!$D$2:$D$21,RAW_Network!$B$2:$B$21,"3",RAW_Network!$C$2:$C$21,"Instagram") | G5: =IFERROR(SUMIFS(RAW_Network!$D$2:$D$21,RAW_Network!$B$2:$B$21,"3",RAW_Network!$C$2:$C$21,"Instagram")/SUMIFS(RAW_Network!$E$2:$E$21,RAW_Network!$B$2:$B$21,"3",RAW_Network!$C$2:$C$21,"Instagram"),"-") | H5: =IFERROR(SUMIFS(RAW_Network!$D$2:$D$21,RAW_Network!$B$2:$B$21,"3",RAW_Network!$C$2:$C$21,"Instagram")/SUMIFS(RAW_Network!$F$2:$F$21,RAW_Network!$B$2:$B$21,"3",RAW_Network!$C$2:$C$21,"Instagram"),"-") | I5: =SUMIFS(RAW_Network!$F$2:$F$21,RAW_Network!$B$2:$B$21,"3",RAW_Network!$C$2:$C$21,"Instagram")
A6: Oct 4 | B6: =SUMIFS(RAW_Network!$D$2:$D$21,RAW_Network!$B$2:$B$21,"4",RAW_Network!$C$2:$C$21,"Facebook") | C6: =IFERROR(SUMIFS(RAW_Network!$D$2:$D$21,RAW_Network!$B$2:$B$21,"4",RAW_Network!$C$2:$C$21,"Facebook")/SUMIFS(RAW_Network!$E$2:$E$21,RAW_Network!$B$2:$B$21,"4",RAW_Network!$C$2:$C$21,"Facebook"),"-") | D6: =IFERROR(SUMIFS(RAW_Network!$D$2:$D$21,RAW_Network!$B$2:$B$21,"4",RAW_Network!$C$2:$C$21,"Facebook")/SUMIFS(RAW_Network!$F$2:$F$21,RAW_Network!$B$2:$B$21,"4",RAW_Network!$C$2:$C$21,"Facebook"),"-") | E6: =SUMIFS(RAW_Network!$F$2:$F$21,RAW_Network!$B$2:$B$21,"4",RAW_Network!$C$2:$C$21,"Facebook") | F6: =SUMIFS(RAW_Network!$D$2:$D$21,RAW_Network!$B$2:$B$21,"4",RAW_Network!$C$2:$C$21,"Instagram") | G6: =IFERROR(SUMIFS(RAW_Network!$D$2:$D$21,RAW_Network!$B$2:$B$21,"4",RAW_Network!$C$2:$C$21,"Instagram")/SUMIFS(RAW_Network!$E$2:$E$21,RAW_Network!$B$2:$B$21,"4",RAW_Network!$C$2:$C$21,"Instagram"),"-") | H6: =IFERROR(SUMIFS(RAW_Network!$D$2:$D$21,RAW_Network!$B$2:$B$21,"4",RAW_Network!$C$2:$C$21,"Instagram")/SUMIFS(RAW_Network!$F$2:$F$21,RAW_Network!$B$2:$B$21,"4",RAW_Network!$C$2:$C$21,"Instagram"),"-") | I6: =SUMIFS(RAW_Network!$F$2:$F$21,RAW_Network!$B$2:$B$21,"4",RAW_Network!$C$2:$C$21,"Instagram")
A7: Oct 5 | B7: =SUMIFS(RAW_Network!$D$2:$D$21,RAW_Network!$B$2:$B$21,"5",RAW_Network!$C$2:$C$21,"Facebook") | C7: =IFERROR(SUMIFS(RAW_Network!$D$2:$D$21,RAW_Network!$B$2:$B$21,"5",RAW_Network!$C$2:$C$21,"Facebook")/SUMIFS(RAW_Network!$E$2:$E$21,RAW_Network!$B$2:$B$21,"5",RAW_Network!$C$2:$C$21,"Facebook"),"-") | D7: =IFERROR(SUMIFS(RAW_Network!$D$2:$D$21,RAW_Network!$B$2:$B$21,"5",RAW_Network!$C$2:$C$21,"Facebook")/SUMIFS(RAW_Network!$F$2:$F$21,RAW_Network!$B$2:$B$21,"5",RAW_Network!$C$2:$C$21,"Facebook"),"-") | E7: =SUMIFS(RAW_Network!$F$2:$F$21,RAW_Network!$B$2:$B$21,"5",RAW_Network!$C$2:$C$21,"Facebook") | F7: =SUMIFS(RAW_Network!$D$2:$D$21,RAW_Network!$B$2:$B$21,"5",RAW_Network!$C$2:$C$21,"Instagram") | G7: =IFERROR(SUMIFS(RAW_Network!$D$2:$D$21,RAW_Network!$B$2:$B$21,"5",RAW_Network!$C$2:$C$21,"Instagram")/SUMIFS(RAW_Network!$E$2:$E$21,RAW_Network!$B$2:$B$21,"5",RAW_Network!$C$2:$C$21,"Instagram"),"-") | H7: =IFERROR(SUMIFS(RAW_Network!$D$2:$D$21,RAW_Network!$B$2:$B$21,"5",RAW_Network!$C$2:$C$21,"Instagram")/SUMIFS(RAW_Network!$F$2:$F$21,RAW_Network!$B$2:$B$21,"5",RAW_Network!$C$2:$C$21,"Instagram"),"-") | I7: =SUMIFS(RAW_Network!$F$2:$F$21,RAW_Network!$B$2:$B$21,"5",RAW_Network!$C$2:$C$21,"Instagram")

Sheet Age Split
A1: AGE SPLIT - share of spend + CPI + Trial CAC, per window. Check whether CAC rises uniformly across age bands (systemic) or in one band (mix shift).
A2: Window | B2: Segment | C2: Spend (Rs) | D2: Spend % | E2: Installs | F2: CPI | G2: Trials | H2: Trial CAC | I2: Inflation
A3: Before Oct 1-2 | B3: 18-24 | C3: =SUMIFS(RAW_Age!$D$2:$D$31,RAW_Age!$B$2:$B$31,">=1",RAW_Age!$B$2:$B$31,"<=2",RAW_Age!$C$2:$C$31,"18-24") | D3: =IFERROR(SUMIFS(RAW_Age!$D$2:$D$31,RAW_Age!$B$2:$B$31,">=1",RAW_Age!$B$2:$B$31,"<=2",RAW_Age!$C$2:$C$31,"18-24")/SUMIFS(RAW_Age!$D$2:$D$31,RAW_Age!$B$2:$B$31,">=1",RAW_Age!$B$2:$B$31,"<=2")*100,"-") | E3: =SUMIFS(RAW_Age!$E$2:$E$31,RAW_Age!$B$2:$B$31,">=1",RAW_Age!$B$2:$B$31,"<=2",RAW_Age!$C$2:$C$31,"18-24") | F3: =IFERROR(SUMIFS(RAW_Age!$D$2:$D$31,RAW_Age!$B$2:$B$31,">=1",RAW_Age!$B$2:$B$31,"<=2",RAW_Age!$C$2:$C$31,"18-24")/SUMIFS(RAW_Age!$E$2:$E$31,RAW_Age!$B$2:$B$31,">=1",RAW_Age!$B$2:$B$31,"<=2",RAW_Age!$C$2:$C$31,"18-24"),"-") | G3: =SUMIFS(RAW_Age!$F$2:$F$31,RAW_Age!$B$2:$B$31,">=1",RAW_Age!$B$2:$B$31,"<=2",RAW_Age!$C$2:$C$31,"18-24") | H3: =IFERROR(SUMIFS(RAW_Age!$D$2:$D$31,RAW_Age!$B$2:$B$31,">=1",RAW_Age!$B$2:$B$31,"<=2",RAW_Age!$C$2:$C$31,"18-24")/SUMIFS(RAW_Age!$F$2:$F$31,RAW_Age!$B$2:$B$31,">=1",RAW_Age!$B$2:$B$31,"<=2",RAW_Age!$C$2:$C$31,"18-24"),"-")
B4: 25-34 | C4: =SUMIFS(RAW_Age!$D$2:$D$31,RAW_Age!$B$2:$B$31,">=1",RAW_Age!$B$2:$B$31,"<=2",RAW_Age!$C$2:$C$31,"25-34") | D4: =IFERROR(SUMIFS(RAW_Age!$D$2:$D$31,RAW_Age!$B$2:$B$31,">=1",RAW_Age!$B$2:$B$31,"<=2",RAW_Age!$C$2:$C$31,"25-34")/SUMIFS(RAW_Age!$D$2:$D$31,RAW_Age!$B$2:$B$31,">=1",RAW_Age!$B$2:$B$31,"<=2")*100,"-") | E4: =SUMIFS(RAW_Age!$E$2:$E$31,RAW_Age!$B$2:$B$31,">=1",RAW_Age!$B$2:$B$31,"<=2",RAW_Age!$C$2:$C$31,"25-34") | F4: =IFERROR(SUMIFS(RAW_Age!$D$2:$D$31,RAW_Age!$B$2:$B$31,">=1",RAW_Age!$B$2:$B$31,"<=2",RAW_Age!$C$2:$C$31,"25-34")/SUMIFS(RAW_Age!$E$2:$E$31,RAW_Age!$B$2:$B$31,">=1",RAW_Age!$B$2:$B$31,"<=2",RAW_Age!$C$2:$C$31,"25-34"),"-") | G4: =SUMIFS(RAW_Age!$F$2:$F$31,RAW_Age!$B$2:$B$31,">=1",RAW_Age!$B$2:$B$31,"<=2",RAW_Age!$C$2:$C$31,"25-34") | H4: =IFERROR(SUMIFS(RAW_Age!$D$2:$D$31,RAW_Age!$B$2:$B$31,">=1",RAW_Age!$B$2:$B$31,"<=2",RAW_Age!$C$2:$C$31,"25-34")/SUMIFS(RAW_Age!$F$2:$F$31,RAW_Age!$B$2:$B$31,">=1",RAW_Age!$B$2:$B$31,"<=2",RAW_Age!$C$2:$C$31,"25-34"),"-")
B5: 35-44 | C5: =SUMIFS(RAW_Age!$D$2:$D$31,RAW_Age!$B$2:$B$31,">=1",RAW_Age!$B$2:$B$31,"<=2",RAW_Age!$C$2:$C$31,"35-44") | D5: =IFERROR(SUMIFS(RAW_Age!$D$2:$D$31,RAW_Age!$B$2:$B$31,">=1",RAW_Age!$B$2:$B$31,"<=2",RAW_Age!$C$2:$C$31,"35-44")/SUMIFS(RAW_Age!$D$2:$D$31,RAW_Age!$B$2:$B$31,">=1",RAW_Age!$B$2:$B$31,"<=2")*100,"-") | E5: =SUMIFS(RAW_Age!$E$2:$E$31,RAW_Age!$B$2:$B$31,">=1",RAW_Age!$B$2:$B$31,"<=2",RAW_Age!$C$2:$C$31,"35-44") | F5: =IFERROR(SUMIFS(RAW_Age!$D$2:$D$31,RAW_Age!$B$2:$B$31,">=1",RAW_Age!$B$2:$B$31,"<=2",RAW_Age!$C$2:$C$31,"35-44")/SUMIFS(RAW_Age!$E$2:$E$31,RAW_Age!$B$2:$B$31,">=1",RAW_Age!$B$2:$B$31,"<=2",RAW_Age!$C$2:$C$31,"35-44"),"-") | G5: =SUMIFS(RAW_Age!$F$2:$F$31,RAW_Age!$B$2:$B$31,">=1",RAW_Age!$B$2:$B$31,"<=2",RAW_Age!$C$2:$C$31,"35-44") | H5: =IFERROR(SUMIFS(RAW_Age!$D$2:$D$31,RAW_Age!$B$2:$B$31,">=1",RAW_Age!$B$2:$B$31,"<=2",RAW_Age!$C$2:$C$31,"35-44")/SUMIFS(RAW_Age!$F$2:$F$31,RAW_Age!$B$2:$B$31,">=1",RAW_Age!$B$2:$B$31,"<=2",RAW_Age!$C$2:$C$31,"35-44"),"-")
B6: 45-54 | C6: =SUMIFS(RAW_Age!$D$2:$D$31,RAW_Age!$B$2:$B$31,">=1",RAW_Age!$B$2:$B$31,"<=2",RAW_Age!$C$2:$C$31,"45-54") | D6: =IFERROR(SUMIFS(RAW_Age!$D$2:$D$31,RAW_Age!$B$2:$B$31,">=1",RAW_Age!$B$2:$B$31,"<=2",RAW_Age!$C$2:$C$31,"45-54")/SUMIFS(RAW_Age!$D$2:$D$31,RAW_Age!$B$2:$B$31,">=1",RAW_Age!$B$2:$B$31,"<=2")*100,"-") | E6: =SUMIFS(RAW_Age!$E$2:$E$31,RAW_Age!$B$2:$B$31,">=1",RAW_Age!$B$2:$B$31,"<=2",RAW_Age!$C$2:$C$31,"45-54") | F6: =IFERROR(SUMIFS(RAW_Age!$D$2:$D$31,RAW_Age!$B$2:$B$31,">=1",RAW_Age!$B$2:$B$31,"<=2",RAW_Age!$C$2:$C$31,"45-54")/SUMIFS(RAW_Age!$E$2:$E$31,RAW_Age!$B$2:$B$31,">=1",RAW_Age!$B$2:$B$31,"<=2",RAW_Age!$C$2:$C$31,"45-54"),"-") | G6: =SUMIFS(RAW_Age!$F$2:$F$31,RAW_Age!$B$2:$B$31,">=1",RAW_Age!$B$2:$B$31,"<=2",RAW_Age!$C$2:$C$31,"45-54") | H6: =IFERROR(SUMIFS(RAW_Age!$D$2:$D$31,RAW_Age!$B$2:$B$31,">=1",RAW_Age!$B$2:$B$31,"<=2",RAW_Age!$C$2:$C$31,"45-54")/SUMIFS(RAW_Age!$F$2:$F$31,RAW_Age!$B$2:$B$31,">=1",RAW_Age!$B$2:$B$31,"<=2",RAW_Age!$C$2:$C$31,"45-54"),"-")
B7: 55-64 | C7: =SUMIFS(RAW_Age!$D$2:$D$31,RAW_Age!$B$2:$B$31,">=1",RAW_Age!$B$2:$B$31,"<=2",RAW_Age!$C$2:$C$31,"55-64") | D7: =IFERROR(SUMIFS(RAW_Age!$D$2:$D$31,RAW_Age!$B$2:$B$31,">=1",RAW_Age!$B$2:$B$31,"<=2",RAW_Age!$C$2:$C$31,"55-64")/SUMIFS(RAW_Age!$D$2:$D$31,RAW_Age!$B$2:$B$31,">=1",RAW_Age!$B$2:$B$31,"<=2")*100,"-") | E7: =SUMIFS(RAW_Age!$E$2:$E$31,RAW_Age!$B$2:$B$31,">=1",RAW_Age!$B$2:$B$31,"<=2",RAW_Age!$C$2:$C$31,"55-64") | F7: =IFERROR(SUMIFS(RAW_Age!$D$2:$D$31,RAW_Age!$B$2:$B$31,">=1",RAW_Age!$B$2:$B$31,"<=2",RAW_Age!$C$2:$C$31,"55-64")/SUMIFS(RAW_Age!$E$2:$E$31,RAW_Age!$B$2:$B$31,">=1",RAW_Age!$B$2:$B$31,"<=2",RAW_Age!$C$2:$C$31,"55-64"),"-") | G7: =SUMIFS(RAW_Age!$F$2:$F$31,RAW_Age!$B$2:$B$31,">=1",RAW_Age!$B$2:$B$31,"<=2",RAW_Age!$C$2:$C$31,"55-64") | H7: =IFERROR(SUMIFS(RAW_Age!$D$2:$D$31,RAW_Age!$B$2:$B$31,">=1",RAW_Age!$B$2:$B$31,"<=2",RAW_Age!$C$2:$C$31,"55-64")/SUMIFS(RAW_Age!$F$2:$F$31,RAW_Age!$B$2:$B$31,">=1",RAW_Age!$B$2:$B$31,"<=2",RAW_Age!$C$2:$C$31,"55-64"),"-")
B8: 65+ | C8: =SUMIFS(RAW_Age!$D$2:$D$31,RAW_Age!$B$2:$B$31,">=1",RAW_Age!$B$2:$B$31,"<=2",RAW_Age!$C$2:$C$31,"65+") | D8: =IFERROR(SUMIFS(RAW_Age!$D$2:$D$31,RAW_Age!$B$2:$B$31,">=1",RAW_Age!$B$2:$B$31,"<=2",RAW_Age!$C$2:$C$31,"65+")/SUMIFS(RAW_Age!$D$2:$D$31,RAW_Age!$B$2:$B$31,">=1",RAW_Age!$B$2:$B$31,"<=2")*100,"-") | E8: =SUMIFS(RAW_Age!$E$2:$E$31,RAW_Age!$B$2:$B$31,">=1",RAW_Age!$B$2:$B$31,"<=2",RAW_Age!$C$2:$C$31,"65+") | F8: =IFERROR(SUMIFS(RAW_Age!$D$2:$D$31,RAW_Age!$B$2:$B$31,">=1",RAW_Age!$B$2:$B$31,"<=2",RAW_Age!$C$2:$C$31,"65+")/SUMIFS(RAW_Age!$E$2:$E$31,RAW_Age!$B$2:$B$31,">=1",RAW_Age!$B$2:$B$31,"<=2",RAW_Age!$C$2:$C$31,"65+"),"-") | G8: =SUMIFS(RAW_Age!$F$2:$F$31,RAW_Age!$B$2:$B$31,">=1",RAW_Age!$B$2:$B$31,"<=2",RAW_Age!$C$2:$C$31,"65+") | H8: =IFERROR(SUMIFS(RAW_Age!$D$2:$D$31,RAW_Age!$B$2:$B$31,">=1",RAW_Age!$B$2:$B$31,"<=2",RAW_Age!$C$2:$C$31,"65+")/SUMIFS(RAW_Age!$F$2:$F$31,RAW_Age!$B$2:$B$31,">=1",RAW_Age!$B$2:$B$31,"<=2",RAW_Age!$C$2:$C$31,"65+"),"-")
A9: After Oct 3-4 | B9: 18-24 | C9: =SUMIFS(RAW_Age!$D$2:$D$31,RAW_Age!$B$2:$B$31,">=3",RAW_Age!$B$2:$B$31,"<=4",RAW_Age!$C$2:$C$31,"18-24") | D9: =IFERROR(SUMIFS(RAW_Age!$D$2:$D$31,RAW_Age!$B$2:$B$31,">=3",RAW_Age!$B$2:$B$31,"<=4",RAW_Age!$C$2:$C$31,"18-24")/SUMIFS(RAW_Age!$D$2:$D$31,RAW_Age!$B$2:$B$31,">=3",RAW_Age!$B$2:$B$31,"<=4")*100,"-") | E9: =SUMIFS(RAW_Age!$E$2:$E$31,RAW_Age!$B$2:$B$31,">=3",RAW_Age!$B$2:$B$31,"<=4",RAW_Age!$C$2:$C$31,"18-24") | F9: =IFERROR(SUMIFS(RAW_Age!$D$2:$D$31,RAW_Age!$B$2:$B$31,">=3",RAW_Age!$B$2:$B$31,"<=4",RAW_Age!$C$2:$C$31,"18-24")/SUMIFS(RAW_Age!$E$2:$E$31,RAW_Age!$B$2:$B$31,">=3",RAW_Age!$B$2:$B$31,"<=4",RAW_Age!$C$2:$C$31,"18-24"),"-") | G9: =SUMIFS(RAW_Age!$F$2:$F$31,RAW_Age!$B$2:$B$31,">=3",RAW_Age!$B$2:$B$31,"<=4",RAW_Age!$C$2:$C$31,"18-24") | H9: =IFERROR(SUMIFS(RAW_Age!$D$2:$D$31,RAW_Age!$B$2:$B$31,">=3",RAW_Age!$B$2:$B$31,"<=4",RAW_Age!$C$2:$C$31,"18-24")/SUMIFS(RAW_Age!$F$2:$F$31,RAW_Age!$B$2:$B$31,">=3",RAW_Age!$B$2:$B$31,"<=4",RAW_Age!$C$2:$C$31,"18-24"),"-") | I9: =IFERROR(F9/F3,"-")
B10: 25-34 | C10: =SUMIFS(RAW_Age!$D$2:$D$31,RAW_Age!$B$2:$B$31,">=3",RAW_Age!$B$2:$B$31,"<=4",RAW_Age!$C$2:$C$31,"25-34") | D10: =IFERROR(SUMIFS(RAW_Age!$D$2:$D$31,RAW_Age!$B$2:$B$31,">=3",RAW_Age!$B$2:$B$31,"<=4",RAW_Age!$C$2:$C$31,"25-34")/SUMIFS(RAW_Age!$D$2:$D$31,RAW_Age!$B$2:$B$31,">=3",RAW_Age!$B$2:$B$31,"<=4")*100,"-") | E10: =SUMIFS(RAW_Age!$E$2:$E$31,RAW_Age!$B$2:$B$31,">=3",RAW_Age!$B$2:$B$31,"<=4",RAW_Age!$C$2:$C$31,"25-34") | F10: =IFERROR(SUMIFS(RAW_Age!$D$2:$D$31,RAW_Age!$B$2:$B$31,">=3",RAW_Age!$B$2:$B$31,"<=4",RAW_Age!$C$2:$C$31,"25-34")/SUMIFS(RAW_Age!$E$2:$E$31,RAW_Age!$B$2:$B$31,">=3",RAW_Age!$B$2:$B$31,"<=4",RAW_Age!$C$2:$C$31,"25-34"),"-") | G10: =SUMIFS(RAW_Age!$F$2:$F$31,RAW_Age!$B$2:$B$31,">=3",RAW_Age!$B$2:$B$31,"<=4",RAW_Age!$C$2:$C$31,"25-34") | H10: =IFERROR(SUMIFS(RAW_Age!$D$2:$D$31,RAW_Age!$B$2:$B$31,">=3",RAW_Age!$B$2:$B$31,"<=4",RAW_Age!$C$2:$C$31,"25-34")/SUMIFS(RAW_Age!$F$2:$F$31,RAW_Age!$B$2:$B$31,">=3",RAW_Age!$B$2:$B$31,"<=4",RAW_Age!$C$2:$C$31,"25-34"),"-") | I10: =IFERROR(F10/F4,"-")
B11: 35-44 | C11: =SUMIFS(RAW_Age!$D$2:$D$31,RAW_Age!$B$2:$B$31,">=3",RAW_Age!$B$2:$B$31,"<=4",RAW_Age!$C$2:$C$31,"35-44") | D11: =IFERROR(SUMIFS(RAW_Age!$D$2:$D$31,RAW_Age!$B$2:$B$31,">=3",RAW_Age!$B$2:$B$31,"<=4",RAW_Age!$C$2:$C$31,"35-44")/SUMIFS(RAW_Age!$D$2:$D$31,RAW_Age!$B$2:$B$31,">=3",RAW_Age!$B$2:$B$31,"<=4")*100,"-") | E11: =SUMIFS(RAW_Age!$E$2:$E$31,RAW_Age!$B$2:$B$31,">=3",RAW_Age!$B$2:$B$31,"<=4",RAW_Age!$C$2:$C$31,"35-44") | F11: =IFERROR(SUMIFS(RAW_Age!$D$2:$D$31,RAW_Age!$B$2:$B$31,">=3",RAW_Age!$B$2:$B$31,"<=4",RAW_Age!$C$2:$C$31,"35-44")/SUMIFS(RAW_Age!$E$2:$E$31,RAW_Age!$B$2:$B$31,">=3",RAW_Age!$B$2:$B$31,"<=4",RAW_Age!$C$2:$C$31,"35-44"),"-") | G11: =SUMIFS(RAW_Age!$F$2:$F$31,RAW_Age!$B$2:$B$31,">=3",RAW_Age!$B$2:$B$31,"<=4",RAW_Age!$C$2:$C$31,"35-44") | H11: =IFERROR(SUMIFS(RAW_Age!$D$2:$D$31,RAW_Age!$B$2:$B$31,">=3",RAW_Age!$B$2:$B$31,"<=4",RAW_Age!$C$2:$C$31,"35-44")/SUMIFS(RAW_Age!$F$2:$F$31,RAW_Age!$B$2:$B$31,">=3",RAW_Age!$B$2:$B$31,"<=4",RAW_Age!$C$2:$C$31,"35-44"),"-") | I11: =IFERROR(F11/F5,"-")
B12: 45-54 | C12: =SUMIFS(RAW_Age!$D$2:$D$31,RAW_Age!$B$2:$B$31,">=3",RAW_Age!$B$2:$B$31,"<=4",RAW_Age!$C$2:$C$31,"45-54") | D12: =IFERROR(SUMIFS(RAW_Age!$D$2:$D$31,RAW_Age!$B$2:$B$31,">=3",RAW_Age!$B$2:$B$31,"<=4",RAW_Age!$C$2:$C$31,"45-54")/SUMIFS(RAW_Age!$D$2:$D$31,RAW_Age!$B$2:$B$31,">=3",RAW_Age!$B$2:$B$31,"<=4")*100,"-") | E12: =SUMIFS(RAW_Age!$E$2:$E$31,RAW_Age!$B$2:$B$31,">=3",RAW_Age!$B$2:$B$31,"<=4",RAW_Age!$C$2:$C$31,"45-54") | F12: =IFERROR(SUMIFS(RAW_Age!$D$2:$D$31,RAW_Age!$B$2:$B$31,">=3",RAW_Age!$B$2:$B$31,"<=4",RAW_Age!$C$2:$C$31,"45-54")/SUMIFS(RAW_Age!$E$2:$E$31,RAW_Age!$B$2:$B$31,">=3",RAW_Age!$B$2:$B$31,"<=4",RAW_Age!$C$2:$C$31,"45-54"),"-") | G12: =SUMIFS(RAW_Age!$F$2:$F$31,RAW_Age!$B$2:$B$31,">=3",RAW_Age!$B$2:$B$31,"<=4",RAW_Age!$C$2:$C$31,"45-54") | H12: =IFERROR(SUMIFS(RAW_Age!$D$2:$D$31,RAW_Age!$B$2:$B$31,">=3",RAW_Age!$B$2:$B$31,"<=4",RAW_Age!$C$2:$C$31,"45-54")/SUMIFS(RAW_Age!$F$2:$F$31,RAW_Age!$B$2:$B$31,">=3",RAW_Age!$B$2:$B$31,"<=4",RAW_Age!$C$2:$C$31,"45-54"),"-") | I12: =IFERROR(F12/F6,"-")
B13: 55-64 | C13: =SUMIFS(RAW_Age!$D$2:$D$31,RAW_Age!$B$2:$B$31,">=3",RAW_Age!$B$2:$B$31,"<=4",RAW_Age!$C$2:$C$31,"55-64") | D13: =IFERROR(SUMIFS(RAW_Age!$D$2:$D$31,RAW_Age!$B$2:$B$31,">=3",RAW_Age!$B$2:$B$31,"<=4",RAW_Age!$C$2:$C$31,"55-64")/SUMIFS(RAW_Age!$D$2:$D$31,RAW_Age!$B$2:$B$31,">=3",RAW_Age!$B$2:$B$31,"<=4")*100,"-") | E13: =SUMIFS(RAW_Age!$E$2:$E$31,RAW_Age!$B$2:$B$31,">=3",RAW_Age!$B$2:$B$31,"<=4",RAW_Age!$C$2:$C$31,"55-64") | F13: =IFERROR(SUMIFS(RAW_Age!$D$2:$D$31,RAW_Age!$B$2:$B$31,">=3",RAW_Age!$B$2:$B$31,"<=4",RAW_Age!$C$2:$C$31,"55-64")/SUMIFS(RAW_Age!$E$2:$E$31,RAW_Age!$B$2:$B$31,">=3",RAW_Age!$B$2:$B$31,"<=4",RAW_Age!$C$2:$C$31,"55-64"),"-") | G13: =SUMIFS(RAW_Age!$F$2:$F$31,RAW_Age!$B$2:$B$31,">=3",RAW_Age!$B$2:$B$31,"<=4",RAW_Age!$C$2:$C$31,"55-64") | H13: =IFERROR(SUMIFS(RAW_Age!$D$2:$D$31,RAW_Age!$B$2:$B$31,">=3",RAW_Age!$B$2:$B$31,"<=4",RAW_Age!$C$2:$C$31,"55-64")/SUMIFS(RAW_Age!$F$2:$F$31,RAW_Age!$B$2:$B$31,">=3",RAW_Age!$B$2:$B$31,"<=4",RAW_Age!$C$2:$C$31,"55-64"),"-") | I13: =IFERROR(F13/F7,"-")
B14: 65+ | C14: =SUMIFS(RAW_Age!$D$2:$D$31,RAW_Age!$B$2:$B$31,">=3",RAW_Age!$B$2:$B$31,"<=4",RAW_Age!$C$2:$C$31,"65+") | D14: =IFERROR(SUMIFS(RAW_Age!$D$2:$D$31,RAW_Age!$B$2:$B$31,">=3",RAW_Age!$B$2:$B$31,"<=4",RAW_Age!$C$2:$C$31,"65+")/SUMIFS(RAW_Age!$D$2:$D$31,RAW_Age!$B$2:$B$31,">=3",RAW_Age!$B$2:$B$31,"<=4")*100,"-") | E14: =SUMIFS(RAW_Age!$E$2:$E$31,RAW_Age!$B$2:$B$31,">=3",RAW_Age!$B$2:$B$31,"<=4",RAW_Age!$C$2:$C$31,"65+") | F14: =IFERROR(SUMIFS(RAW_Age!$D$2:$D$31,RAW_Age!$B$2:$B$31,">=3",RAW_Age!$B$2:$B$31,"<=4",RAW_Age!$C$2:$C$31,"65+")/SUMIFS(RAW_Age!$E$2:$E$31,RAW_Age!$B$2:$B$31,">=3",RAW_Age!$B$2:$B$31,"<=4",RAW_Age!$C$2:$C$31,"65+"),"-") | G14: =SUMIFS(RAW_Age!$F$2:$F$31,RAW_Age!$B$2:$B$31,">=3",RAW_Age!$B$2:$B$31,"<=4",RAW_Age!$C$2:$C$31,"65+") | H14: =IFERROR(SUMIFS(RAW_Age!$D$2:$D$31,RAW_Age!$B$2:$B$31,">=3",RAW_Age!$B$2:$B$31,"<=4",RAW_Age!$C$2:$C$31,"65+")/SUMIFS(RAW_Age!$F$2:$F$31,RAW_Age!$B$2:$B$31,">=3",RAW_Age!$B$2:$B$31,"<=4",RAW_Age!$C$2:$C$31,"65+"),"-") | I14: =IFERROR(F14/F8,"-")

Sheet Gender Split
A1: GENDER SPLIT - share of spend + CPI + Trial CAC, per window. Mix is stable (~80% male); check both degrade together.
A2: Window | B2: Segment | C2: Spend (Rs) | D2: Spend % | E2: Installs | F2: CPI | G2: Trials | H2: Trial CAC | I2: Inflation
A3: Before Oct 1-2 | B3: Male | C3: =SUMIFS(RAW_Gender!$D$2:$D$11,RAW_Gender!$B$2:$B$11,">=1",RAW_Gender!$B$2:$B$11,"<=2",RAW_Gender!$C$2:$C$11,"Male") | D3: =IFERROR(SUMIFS(RAW_Gender!$D$2:$D$11,RAW_Gender!$B$2:$B$11,">=1",RAW_Gender!$B$2:$B$11,"<=2",RAW_Gender!$C$2:$C$11,"Male")/SUMIFS(RAW_Gender!$D$2:$D$11,RAW_Gender!$B$2:$B$11,">=1",RAW_Gender!$B$2:$B$11,"<=2")*100,"-") | E3: =SUMIFS(RAW_Gender!$E$2:$E$11,RAW_Gender!$B$2:$B$11,">=1",RAW_Gender!$B$2:$B$11,"<=2",RAW_Gender!$C$2:$C$11,"Male") | F3: =IFERROR(SUMIFS(RAW_Gender!$D$2:$D$11,RAW_Gender!$B$2:$B$11,">=1",RAW_Gender!$B$2:$B$11,"<=2",RAW_Gender!$C$2:$C$11,"Male")/SUMIFS(RAW_Gender!$E$2:$E$11,RAW_Gender!$B$2:$B$11,">=1",RAW_Gender!$B$2:$B$11,"<=2",RAW_Gender!$C$2:$C$11,"Male"),"-") | G3: =SUMIFS(RAW_Gender!$F$2:$F$11,RAW_Gender!$B$2:$B$11,">=1",RAW_Gender!$B$2:$B$11,"<=2",RAW_Gender!$C$2:$C$11,"Male") | H3: =IFERROR(SUMIFS(RAW_Gender!$D$2:$D$11,RAW_Gender!$B$2:$B$11,">=1",RAW_Gender!$B$2:$B$11,"<=2",RAW_Gender!$C$2:$C$11,"Male")/SUMIFS(RAW_Gender!$F$2:$F$11,RAW_Gender!$B$2:$B$11,">=1",RAW_Gender!$B$2:$B$11,"<=2",RAW_Gender!$C$2:$C$11,"Male"),"-")
B4: Female | C4: =SUMIFS(RAW_Gender!$D$2:$D$11,RAW_Gender!$B$2:$B$11,">=1",RAW_Gender!$B$2:$B$11,"<=2",RAW_Gender!$C$2:$C$11,"Female") | D4: =IFERROR(SUMIFS(RAW_Gender!$D$2:$D$11,RAW_Gender!$B$2:$B$11,">=1",RAW_Gender!$B$2:$B$11,"<=2",RAW_Gender!$C$2:$C$11,"Female")/SUMIFS(RAW_Gender!$D$2:$D$11,RAW_Gender!$B$2:$B$11,">=1",RAW_Gender!$B$2:$B$11,"<=2")*100,"-") | E4: =SUMIFS(RAW_Gender!$E$2:$E$11,RAW_Gender!$B$2:$B$11,">=1",RAW_Gender!$B$2:$B$11,"<=2",RAW_Gender!$C$2:$C$11,"Female") | F4: =IFERROR(SUMIFS(RAW_Gender!$D$2:$D$11,RAW_Gender!$B$2:$B$11,">=1",RAW_Gender!$B$2:$B$11,"<=2",RAW_Gender!$C$2:$C$11,"Female")/SUMIFS(RAW_Gender!$E$2:$E$11,RAW_Gender!$B$2:$B$11,">=1",RAW_Gender!$B$2:$B$11,"<=2",RAW_Gender!$C$2:$C$11,"Female"),"-") | G4: =SUMIFS(RAW_Gender!$F$2:$F$11,RAW_Gender!$B$2:$B$11,">=1",RAW_Gender!$B$2:$B$11,"<=2",RAW_Gender!$C$2:$C$11,"Female") | H4: =IFERROR(SUMIFS(RAW_Gender!$D$2:$D$11,RAW_Gender!$B$2:$B$11,">=1",RAW_Gender!$B$2:$B$11,"<=2",RAW_Gender!$C$2:$C$11,"Female")/SUMIFS(RAW_Gender!$F$2:$F$11,RAW_Gender!$B$2:$B$11,">=1",RAW_Gender!$B$2:$B$11,"<=2",RAW_Gender!$C$2:$C$11,"Female"),"-")
A5: After Oct 3-4 | B5: Male | C5: =SUMIFS(RAW_Gender!$D$2:$D$11,RAW_Gender!$B$2:$B$11,">=3",RAW_Gender!$B$2:$B$11,"<=4",RAW_Gender!$C$2:$C$11,"Male") | D5: =IFERROR(SUMIFS(RAW_Gender!$D$2:$D$11,RAW_Gender!$B$2:$B$11,">=3",RAW_Gender!$B$2:$B$11,"<=4",RAW_Gender!$C$2:$C$11,"Male")/SUMIFS(RAW_Gender!$D$2:$D$11,RAW_Gender!$B$2:$B$11,">=3",RAW_Gender!$B$2:$B$11,"<=4")*100,"-") | E5: =SUMIFS(RAW_Gender!$E$2:$E$11,RAW_Gender!$B$2:$B$11,">=3",RAW_Gender!$B$2:$B$11,"<=4",RAW_Gender!$C$2:$C$11,"Male") | F5: =IFERROR(SUMIFS(RAW_Gender!$D$2:$D$11,RAW_Gender!$B$2:$B$11,">=3",RAW_Gender!$B$2:$B$11,"<=4",RAW_Gender!$C$2:$C$11,"Male")/SUMIFS(RAW_Gender!$E$2:$E$11,RAW_Gender!$B$2:$B$11,">=3",RAW_Gender!$B$2:$B$11,"<=4",RAW_Gender!$C$2:$C$11,"Male"),"-") | G5: =SUMIFS(RAW_Gender!$F$2:$F$11,RAW_Gender!$B$2:$B$11,">=3",RAW_Gender!$B$2:$B$11,"<=4",RAW_Gender!$C$2:$C$11,"Male") | H5: =IFERROR(SUMIFS(RAW_Gender!$D$2:$D$11,RAW_Gender!$B$2:$B$11,">=3",RAW_Gender!$B$2:$B$11,"<=4",RAW_Gender!$C$2:$C$11,"Male")/SUMIFS(RAW_Gender!$F$2:$F$11,RAW_Gender!$B$2:$B$11,">=3",RAW_Gender!$B$2:$B$11,"<=4",RAW_Gender!$C$2:$C$11,"Male"),"-") | I5: =IFERROR(F5/F3,"-")
B6: Female | C6: =SUMIFS(RAW_Gender!$D$2:$D$11,RAW_Gender!$B$2:$B$11,">=3",RAW_Gender!$B$2:$B$11,"<=4",RAW_Gender!$C$2:$C$11,"Female") | D6: =IFERROR(SUMIFS(RAW_Gender!$D$2:$D$11,RAW_Gender!$B$2:$B$11,">=3",RAW_Gender!$B$2:$B$11,"<=4",RAW_Gender!$C$2:$C$11,"Female")/SUMIFS(RAW_Gender!$D$2:$D$11,RAW_Gender!$B$2:$B$11,">=3",RAW_Gender!$B$2:$B$11,"<=4")*100,"-") | E6: =SUMIFS(RAW_Gender!$E$2:$E$11,RAW_Gender!$B$2:$B$11,">=3",RAW_Gender!$B$2:$B$11,"<=4",RAW_Gender!$C$2:$C$11,"Female") | F6: =IFERROR(SUMIFS(RAW_Gender!$D$2:$D$11,RAW_Gender!$B$2:$B$11,">=3",RAW_Gender!$B$2:$B$11,"<=4",RAW_Gender!$C$2:$C$11,"Female")/SUMIFS(RAW_Gender!$E$2:$E$11,RAW_Gender!$B$2:$B$11,">=3",RAW_Gender!$B$2:$B$11,"<=4",RAW_Gender!$C$2:$C$11,"Female"),"-") | G6: =SUMIFS(RAW_Gender!$F$2:$F$11,RAW_Gender!$B$2:$B$11,">=3",RAW_Gender!$B$2:$B$11,"<=4",RAW_Gender!$C$2:$C$11,"Female") | H6: =IFERROR(SUMIFS(RAW_Gender!$D$2:$D$11,RAW_Gender!$B$2:$B$11,">=3",RAW_Gender!$B$2:$B$11,"<=4",RAW_Gender!$C$2:$C$11,"Female")/SUMIFS(RAW_Gender!$F$2:$F$11,RAW_Gender!$B$2:$B$11,">=3",RAW_Gender!$B$2:$B$11,"<=4",RAW_Gender!$C$2:$C$11,"Female"),"-") | I6: =IFERROR(F6/F4,"-")

Sheet Placement Split
A1: PLACEMENT SPLIT - top placements, share of spend + CPI + Trial CAC. Inflation = After CPI / Before CPI. Broad rise = systemic.
A2: Window | B2: Segment | C2: Spend (Rs) | D2: Spend % | E2: Installs | F2: CPI | G2: Trials | H2: Trial CAC | I2: Inflation
A3: Before Oct 1-2 | B3: Facebook Reels | C3: =SUMIFS(RAW_Placement!$D$2:$D$36,RAW_Placement!$B$2:$B$36,">=1",RAW_Placement!$B$2:$B$36,"<=2",RAW_Placement!$C$2:$C$36,"Facebook Reels") | D3: =IFERROR(SUMIFS(RAW_Placement!$D$2:$D$36,RAW_Placement!$B$2:$B$36,">=1",RAW_Placement!$B$2:$B$36,"<=2",RAW_Placement!$C$2:$C$36,"Facebook Reels")/SUMIFS(RAW_Placement!$D$2:$D$36,RAW_Placement!$B$2:$B$36,">=1",RAW_Placement!$B$2:$B$36,"<=2")*100,"-") | E3: =SUMIFS(RAW_Placement!$E$2:$E$36,RAW_Placement!$B$2:$B$36,">=1",RAW_Placement!$B$2:$B$36,"<=2",RAW_Placement!$C$2:$C$36,"Facebook Reels") | F3: =IFERROR(SUMIFS(RAW_Placement!$D$2:$D$36,RAW_Placement!$B$2:$B$36,">=1",RAW_Placement!$B$2:$B$36,"<=2",RAW_Placement!$C$2:$C$36,"Facebook Reels")/SUMIFS(RAW_Placement!$E$2:$E$36,RAW_Placement!$B$2:$B$36,">=1",RAW_Placement!$B$2:$B$36,"<=2",RAW_Placement!$C$2:$C$36,"Facebook Reels"),"-") | G3: =SUMIFS(RAW_Placement!$F$2:$F$36,RAW_Placement!$B$2:$B$36,">=1",RAW_Placement!$B$2:$B$36,"<=2",RAW_Placement!$C$2:$C$36,"Facebook Reels") | H3: =IFERROR(SUMIFS(RAW_Placement!$D$2:$D$36,RAW_Placement!$B$2:$B$36,">=1",RAW_Placement!$B$2:$B$36,"<=2",RAW_Placement!$C$2:$C$36,"Facebook Reels")/SUMIFS(RAW_Placement!$F$2:$F$36,RAW_Placement!$B$2:$B$36,">=1",RAW_Placement!$B$2:$B$36,"<=2",RAW_Placement!$C$2:$C$36,"Facebook Reels"),"-")
B4: Facebook Feed | C4: =SUMIFS(RAW_Placement!$D$2:$D$36,RAW_Placement!$B$2:$B$36,">=1",RAW_Placement!$B$2:$B$36,"<=2",RAW_Placement!$C$2:$C$36,"Facebook Feed") | D4: =IFERROR(SUMIFS(RAW_Placement!$D$2:$D$36,RAW_Placement!$B$2:$B$36,">=1",RAW_Placement!$B$2:$B$36,"<=2",RAW_Placement!$C$2:$C$36,"Facebook Feed")/SUMIFS(RAW_Placement!$D$2:$D$36,RAW_Placement!$B$2:$B$36,">=1",RAW_Placement!$B$2:$B$36,"<=2")*100,"-") | E4: =SUMIFS(RAW_Placement!$E$2:$E$36,RAW_Placement!$B$2:$B$36,">=1",RAW_Placement!$B$2:$B$36,"<=2",RAW_Placement!$C$2:$C$36,"Facebook Feed") | F4: =IFERROR(SUMIFS(RAW_Placement!$D$2:$D$36,RAW_Placement!$B$2:$B$36,">=1",RAW_Placement!$B$2:$B$36,"<=2",RAW_Placement!$C$2:$C$36,"Facebook Feed")/SUMIFS(RAW_Placement!$E$2:$E$36,RAW_Placement!$B$2:$B$36,">=1",RAW_Placement!$B$2:$B$36,"<=2",RAW_Placement!$C$2:$C$36,"Facebook Feed"),"-") | G4: =SUMIFS(RAW_Placement!$F$2:$F$36,RAW_Placement!$B$2:$B$36,">=1",RAW_Placement!$B$2:$B$36,"<=2",RAW_Placement!$C$2:$C$36,"Facebook Feed") | H4: =IFERROR(SUMIFS(RAW_Placement!$D$2:$D$36,RAW_Placement!$B$2:$B$36,">=1",RAW_Placement!$B$2:$B$36,"<=2",RAW_Placement!$C$2:$C$36,"Facebook Feed")/SUMIFS(RAW_Placement!$F$2:$F$36,RAW_Placement!$B$2:$B$36,">=1",RAW_Placement!$B$2:$B$36,"<=2",RAW_Placement!$C$2:$C$36,"Facebook Feed"),"-")
B5: Instagram Reels | C5: =SUMIFS(RAW_Placement!$D$2:$D$36,RAW_Placement!$B$2:$B$36,">=1",RAW_Placement!$B$2:$B$36,"<=2",RAW_Placement!$C$2:$C$36,"Instagram Reels") | D5: =IFERROR(SUMIFS(RAW_Placement!$D$2:$D$36,RAW_Placement!$B$2:$B$36,">=1",RAW_Placement!$B$2:$B$36,"<=2",RAW_Placement!$C$2:$C$36,"Instagram Reels")/SUMIFS(RAW_Placement!$D$2:$D$36,RAW_Placement!$B$2:$B$36,">=1",RAW_Placement!$B$2:$B$36,"<=2")*100,"-") | E5: =SUMIFS(RAW_Placement!$E$2:$E$36,RAW_Placement!$B$2:$B$36,">=1",RAW_Placement!$B$2:$B$36,"<=2",RAW_Placement!$C$2:$C$36,"Instagram Reels") | F5: =IFERROR(SUMIFS(RAW_Placement!$D$2:$D$36,RAW_Placement!$B$2:$B$36,">=1",RAW_Placement!$B$2:$B$36,"<=2",RAW_Placement!$C$2:$C$36,"Instagram Reels")/SUMIFS(RAW_Placement!$E$2:$E$36,RAW_Placement!$B$2:$B$36,">=1",RAW_Placement!$B$2:$B$36,"<=2",RAW_Placement!$C$2:$C$36,"Instagram Reels"),"-") | G5: =SUMIFS(RAW_Placement!$F$2:$F$36,RAW_Placement!$B$2:$B$36,">=1",RAW_Placement!$B$2:$B$36,"<=2",RAW_Placement!$C$2:$C$36,"Instagram Reels") | H5: =IFERROR(SUMIFS(RAW_Placement!$D$2:$D$36,RAW_Placement!$B$2:$B$36,">=1",RAW_Placement!$B$2:$B$36,"<=2",RAW_Placement!$C$2:$C$36,"Instagram Reels")/SUMIFS(RAW_Placement!$F$2:$F$36,RAW_Placement!$B$2:$B$36,">=1",RAW_Placement!$B$2:$B$36,"<=2",RAW_Placement!$C$2:$C$36,"Instagram Reels"),"-")
B6: Instagram Feed | C6: =SUMIFS(RAW_Placement!$D$2:$D$36,RAW_Placement!$B$2:$B$36,">=1",RAW_Placement!$B$2:$B$36,"<=2",RAW_Placement!$C$2:$C$36,"Instagram Feed") | D6: =IFERROR(SUMIFS(RAW_Placement!$D$2:$D$36,RAW_Placement!$B$2:$B$36,">=1",RAW_Placement!$B$2:$B$36,"<=2",RAW_Placement!$C$2:$C$36,"Instagram Feed")/SUMIFS(RAW_Placement!$D$2:$D$36,RAW_Placement!$B$2:$B$36,">=1",RAW_Placement!$B$2:$B$36,"<=2")*100,"-") | E6: =SUMIFS(RAW_Placement!$E$2:$E$36,RAW_Placement!$B$2:$B$36,">=1",RAW_Placement!$B$2:$B$36,"<=2",RAW_Placement!$C$2:$C$36,"Instagram Feed") | F6: =IFERROR(SUMIFS(RAW_Placement!$D$2:$D$36,RAW_Placement!$B$2:$B$36,">=1",RAW_Placement!$B$2:$B$36,"<=2",RAW_Placement!$C$2:$C$36,"Instagram Feed")/SUMIFS(RAW_Placement!$E$2:$E$36,RAW_Placement!$B$2:$B$36,">=1",RAW_Placement!$B$2:$B$36,"<=2",RAW_Placement!$C$2:$C$36,"Instagram Feed"),"-") | G6: =SUMIFS(RAW_Placement!$F$2:$F$36,RAW_Placement!$B$2:$B$36,">=1",RAW_Placement!$B$2:$B$36,"<=2",RAW_Placement!$C$2:$C$36,"Instagram Feed") | H6: =IFERROR(SUMIFS(RAW_Placement!$D$2:$D$36,RAW_Placement!$B$2:$B$36,">=1",RAW_Placement!$B$2:$B$36,"<=2",RAW_Placement!$C$2:$C$36,"Instagram Feed")/SUMIFS(RAW_Placement!$F$2:$F$36,RAW_Placement!$B$2:$B$36,">=1",RAW_Placement!$B$2:$B$36,"<=2",RAW_Placement!$C$2:$C$36,"Instagram Feed"),"-")
B7: Facebook Stories | C7: =SUMIFS(RAW_Placement!$D$2:$D$36,RAW_Placement!$B$2:$B$36,">=1",RAW_Placement!$B$2:$B$36,"<=2",RAW_Placement!$C$2:$C$36,"Facebook Stories") | D7: =IFERROR(SUMIFS(RAW_Placement!$D$2:$D$36,RAW_Placement!$B$2:$B$36,">=1",RAW_Placement!$B$2:$B$36,"<=2",RAW_Placement!$C$2:$C$36,"Facebook Stories")/SUMIFS(RAW_Placement!$D$2:$D$36,RAW_Placement!$B$2:$B$36,">=1",RAW_Placement!$B$2:$B$36,"<=2")*100,"-") | E7: =SUMIFS(RAW_Placement!$E$2:$E$36,RAW_Placement!$B$2:$B$36,">=1",RAW_Placement!$B$2:$B$36,"<=2",RAW_Placement!$C$2:$C$36,"Facebook Stories") | F7: =IFERROR(SUMIFS(RAW_Placement!$D$2:$D$36,RAW_Placement!$B$2:$B$36,">=1",RAW_Placement!$B$2:$B$36,"<=2",RAW_Placement!$C$2:$C$36,"Facebook Stories")/SUMIFS(RAW_Placement!$E$2:$E$36,RAW_Placement!$B$2:$B$36,">=1",RAW_Placement!$B$2:$B$36,"<=2",RAW_Placement!$C$2:$C$36,"Facebook Stories"),"-") | G7: =SUMIFS(RAW_Placement!$F$2:$F$36,RAW_Placement!$B$2:$B$36,">=1",RAW_Placement!$B$2:$B$36,"<=2",RAW_Placement!$C$2:$C$36,"Facebook Stories") | H7: =IFERROR(SUMIFS(RAW_Placement!$D$2:$D$36,RAW_Placement!$B$2:$B$36,">=1",RAW_Placement!$B$2:$B$36,"<=2",RAW_Placement!$C$2:$C$36,"Facebook Stories")/SUMIFS(RAW_Placement!$F$2:$F$36,RAW_Placement!$B$2:$B$36,">=1",RAW_Placement!$B$2:$B$36,"<=2",RAW_Placement!$C$2:$C$36,"Facebook Stories"),"-")
B8: Instream Video | C8: =SUMIFS(RAW_Placement!$D$2:$D$36,RAW_Placement!$B$2:$B$36,">=1",RAW_Placement!$B$2:$B$36,"<=2",RAW_Placement!$C$2:$C$36,"Instream Video") | D8: =IFERROR(SUMIFS(RAW_Placement!$D$2:$D$36,RAW_Placement!$B$2:$B$36,">=1",RAW_Placement!$B$2:$B$36,"<=2",RAW_Placement!$C$2:$C$36,"Instream Video")/SUMIFS(RAW_Placement!$D$2:$D$36,RAW_Placement!$B$2:$B$36,">=1",RAW_Placement!$B$2:$B$36,"<=2")*100,"-") | E8: =SUMIFS(RAW_Placement!$E$2:$E$36,RAW_Placement!$B$2:$B$36,">=1",RAW_Placement!$B$2:$B$36,"<=2",RAW_Placement!$C$2:$C$36,"Instream Video") | F8: =IFERROR(SUMIFS(RAW_Placement!$D$2:$D$36,RAW_Placement!$B$2:$B$36,">=1",RAW_Placement!$B$2:$B$36,"<=2",RAW_Placement!$C$2:$C$36,"Instream Video")/SUMIFS(RAW_Placement!$E$2:$E$36,RAW_Placement!$B$2:$B$36,">=1",RAW_Placement!$B$2:$B$36,"<=2",RAW_Placement!$C$2:$C$36,"Instream Video"),"-") | G8: =SUMIFS(RAW_Placement!$F$2:$F$36,RAW_Placement!$B$2:$B$36,">=1",RAW_Placement!$B$2:$B$36,"<=2",RAW_Placement!$C$2:$C$36,"Instream Video") | H8: =IFERROR(SUMIFS(RAW_Placement!$D$2:$D$36,RAW_Placement!$B$2:$B$36,">=1",RAW_Placement!$B$2:$B$36,"<=2",RAW_Placement!$C$2:$C$36,"Instream Video")/SUMIFS(RAW_Placement!$F$2:$F$36,RAW_Placement!$B$2:$B$36,">=1",RAW_Placement!$B$2:$B$36,"<=2",RAW_Placement!$C$2:$C$36,"Instream Video"),"-")
B9: Instagram Stories | C9: =SUMIFS(RAW_Placement!$D$2:$D$36,RAW_Placement!$B$2:$B$36,">=1",RAW_Placement!$B$2:$B$36,"<=2",RAW_Placement!$C$2:$C$36,"Instagram Stories") | D9: =IFERROR(SUMIFS(RAW_Placement!$D$2:$D$36,RAW_Placement!$B$2:$B$36,">=1",RAW_Placement!$B$2:$B$36,"<=2",RAW_Placement!$C$2:$C$36,"Instagram Stories")/SUMIFS(RAW_Placement!$D$2:$D$36,RAW_Placement!$B$2:$B$36,">=1",RAW_Placement!$B$2:$B$36,"<=2")*100,"-") | E9: =SUMIFS(RAW_Placement!$E$2:$E$36,RAW_Placement!$B$2:$B$36,">=1",RAW_Placement!$B$2:$B$36,"<=2",RAW_Placement!$C$2:$C$36,"Instagram Stories") | F9: =IFERROR(SUMIFS(RAW_Placement!$D$2:$D$36,RAW_Placement!$B$2:$B$36,">=1",RAW_Placement!$B$2:$B$36,"<=2",RAW_Placement!$C$2:$C$36,"Instagram Stories")/SUMIFS(RAW_Placement!$E$2:$E$36,RAW_Placement!$B$2:$B$36,">=1",RAW_Placement!$B$2:$B$36,"<=2",RAW_Placement!$C$2:$C$36,"Instagram Stories"),"-") | G9: =SUMIFS(RAW_Placement!$F$2:$F$36,RAW_Placement!$B$2:$B$36,">=1",RAW_Placement!$B$2:$B$36,"<=2",RAW_Placement!$C$2:$C$36,"Instagram Stories") | H9: =IFERROR(SUMIFS(RAW_Placement!$D$2:$D$36,RAW_Placement!$B$2:$B$36,">=1",RAW_Placement!$B$2:$B$36,"<=2",RAW_Placement!$C$2:$C$36,"Instagram Stories")/SUMIFS(RAW_Placement!$F$2:$F$36,RAW_Placement!$B$2:$B$36,">=1",RAW_Placement!$B$2:$B$36,"<=2",RAW_Placement!$C$2:$C$36,"Instagram Stories"),"-")
A10: After Oct 3-4 | B10: Facebook Reels | C10: =SUMIFS(RAW_Placement!$D$2:$D$36,RAW_Placement!$B$2:$B$36,">=3",RAW_Placement!$B$2:$B$36,"<=4",RAW_Placement!$C$2:$C$36,"Facebook Reels") | D10: =IFERROR(SUMIFS(RAW_Placement!$D$2:$D$36,RAW_Placement!$B$2:$B$36,">=3",RAW_Placement!$B$2:$B$36,"<=4",RAW_Placement!$C$2:$C$36,"Facebook Reels")/SUMIFS(RAW_Placement!$D$2:$D$36,RAW_Placement!$B$2:$B$36,">=3",RAW_Placement!$B$2:$B$36,"<=4")*100,"-") | E10: =SUMIFS(RAW_Placement!$E$2:$E$36,RAW_Placement!$B$2:$B$36,">=3",RAW_Placement!$B$2:$B$36,"<=4",RAW_Placement!$C$2:$C$36,"Facebook Reels") | F10: =IFERROR(SUMIFS(RAW_Placement!$D$2:$D$36,RAW_Placement!$B$2:$B$36,">=3",RAW_Placement!$B$2:$B$36,"<=4",RAW_Placement!$C$2:$C$36,"Facebook Reels")/SUMIFS(RAW_Placement!$E$2:$E$36,RAW_Placement!$B$2:$B$36,">=3",RAW_Placement!$B$2:$B$36,"<=4",RAW_Placement!$C$2:$C$36,"Facebook Reels"),"-") | G10: =SUMIFS(RAW_Placement!$F$2:$F$36,RAW_Placement!$B$2:$B$36,">=3",RAW_Placement!$B$2:$B$36,"<=4",RAW_Placement!$C$2:$C$36,"Facebook Reels") | H10: =IFERROR(SUMIFS(RAW_Placement!$D$2:$D$36,RAW_Placement!$B$2:$B$36,">=3",RAW_Placement!$B$2:$B$36,"<=4",RAW_Placement!$C$2:$C$36,"Facebook Reels")/SUMIFS(RAW_Placement!$F$2:$F$36,RAW_Placement!$B$2:$B$36,">=3",RAW_Placement!$B$2:$B$36,"<=4",RAW_Placement!$C$2:$C$36,"Facebook Reels"),"-") | I10: =IFERROR(F10/F3,"-")
B11: Facebook Feed | C11: =SUMIFS(RAW_Placement!$D$2:$D$36,RAW_Placement!$B$2:$B$36,">=3",RAW_Placement!$B$2:$B$36,"<=4",RAW_Placement!$C$2:$C$36,"Facebook Feed") | D11: =IFERROR(SUMIFS(RAW_Placement!$D$2:$D$36,RAW_Placement!$B$2:$B$36,">=3",RAW_Placement!$B$2:$B$36,"<=4",RAW_Placement!$C$2:$C$36,"Facebook Feed")/SUMIFS(RAW_Placement!$D$2:$D$36,RAW_Placement!$B$2:$B$36,">=3",RAW_Placement!$B$2:$B$36,"<=4")*100,"-") | E11: =SUMIFS(RAW_Placement!$E$2:$E$36,RAW_Placement!$B$2:$B$36,">=3",RAW_Placement!$B$2:$B$36,"<=4",RAW_Placement!$C$2:$C$36,"Facebook Feed") | F11: =IFERROR(SUMIFS(RAW_Placement!$D$2:$D$36,RAW_Placement!$B$2:$B$36,">=3",RAW_Placement!$B$2:$B$36,"<=4",RAW_Placement!$C$2:$C$36,"Facebook Feed")/SUMIFS(RAW_Placement!$E$2:$E$36,RAW_Placement!$B$2:$B$36,">=3",RAW_Placement!$B$2:$B$36,"<=4",RAW_Placement!$C$2:$C$36,"Facebook Feed"),"-") | G11: =SUMIFS(RAW_Placement!$F$2:$F$36,RAW_Placement!$B$2:$B$36,">=3",RAW_Placement!$B$2:$B$36,"<=4",RAW_Placement!$C$2:$C$36,"Facebook Feed") | H11: =IFERROR(SUMIFS(RAW_Placement!$D$2:$D$36,RAW_Placement!$B$2:$B$36,">=3",RAW_Placement!$B$2:$B$36,"<=4",RAW_Placement!$C$2:$C$36,"Facebook Feed")/SUMIFS(RAW_Placement!$F$2:$F$36,RAW_Placement!$B$2:$B$36,">=3",RAW_Placement!$B$2:$B$36,"<=4",RAW_Placement!$C$2:$C$36,"Facebook Feed"),"-") | I11: =IFERROR(F11/F4,"-")
B12: Instagram Reels | C12: =SUMIFS(RAW_Placement!$D$2:$D$36,RAW_Placement!$B$2:$B$36,">=3",RAW_Placement!$B$2:$B$36,"<=4",RAW_Placement!$C$2:$C$36,"Instagram Reels") | D12: =IFERROR(SUMIFS(RAW_Placement!$D$2:$D$36,RAW_Placement!$B$2:$B$36,">=3",RAW_Placement!$B$2:$B$36,"<=4",RAW_Placement!$C$2:$C$36,"Instagram Reels")/SUMIFS(RAW_Placement!$D$2:$D$36,RAW_Placement!$B$2:$B$36,">=3",RAW_Placement!$B$2:$B$36,"<=4")*100,"-") | E12: =SUMIFS(RAW_Placement!$E$2:$E$36,RAW_Placement!$B$2:$B$36,">=3",RAW_Placement!$B$2:$B$36,"<=4",RAW_Placement!$C$2:$C$36,"Instagram Reels") | F12: =IFERROR(SUMIFS(RAW_Placement!$D$2:$D$36,RAW_Placement!$B$2:$B$36,">=3",RAW_Placement!$B$2:$B$36,"<=4",RAW_Placement!$C$2:$C$36,"Instagram Reels")/SUMIFS(RAW_Placement!$E$2:$E$36,RAW_Placement!$B$2:$B$36,">=3",RAW_Placement!$B$2:$B$36,"<=4",RAW_Placement!$C$2:$C$36,"Instagram Reels"),"-") | G12: =SUMIFS(RAW_Placement!$F$2:$F$36,RAW_Placement!$B$2:$B$36,">=3",RAW_Placement!$B$2:$B$36,"<=4",RAW_Placement!$C$2:$C$36,"Instagram Reels") | H12: =IFERROR(SUMIFS(RAW_Placement!$D$2:$D$36,RAW_Placement!$B$2:$B$36,">=3",RAW_Placement!$B$2:$B$36,"<=4",RAW_Placement!$C$2:$C$36,"Instagram Reels")/SUMIFS(RAW_Placement!$F$2:$F$36,RAW_Placement!$B$2:$B$36,">=3",RAW_Placement!$B$2:$B$36,"<=4",RAW_Placement!$C$2:$C$36,"Instagram Reels"),"-") | I12: =IFERROR(F12/F5,"-")
B13: Instagram Feed | C13: =SUMIFS(RAW_Placement!$D$2:$D$36,RAW_Placement!$B$2:$B$36,">=3",RAW_Placement!$B$2:$B$36,"<=4",RAW_Placement!$C$2:$C$36,"Instagram Feed") | D13: =IFERROR(SUMIFS(RAW_Placement!$D$2:$D$36,RAW_Placement!$B$2:$B$36,">=3",RAW_Placement!$B$2:$B$36,"<=4",RAW_Placement!$C$2:$C$36,"Instagram Feed")/SUMIFS(RAW_Placement!$D$2:$D$36,RAW_Placement!$B$2:$B$36,">=3",RAW_Placement!$B$2:$B$36,"<=4")*100,"-") | E13: =SUMIFS(RAW_Placement!$E$2:$E$36,RAW_Placement!$B$2:$B$36,">=3",RAW_Placement!$B$2:$B$36,"<=4",RAW_Placement!$C$2:$C$36,"Instagram Feed") | F13: =IFERROR(SUMIFS(RAW_Placement!$D$2:$D$36,RAW_Placement!$B$2:$B$36,">=3",RAW_Placement!$B$2:$B$36,"<=4",RAW_Placement!$C$2:$C$36,"Instagram Feed")/SUMIFS(RAW_Placement!$E$2:$E$36,RAW_Placement!$B$2:$B$36,">=3",RAW_Placement!$B$2:$B$36,"<=4",RAW_Placement!$C$2:$C$36,"Instagram Feed"),"-") | G13: =SUMIFS(RAW_Placement!$F$2:$F$36,RAW_Placement!$B$2:$B$36,">=3",RAW_Placement!$B$2:$B$36,"<=4",RAW_Placement!$C$2:$C$36,"Instagram Feed") | H13: =IFERROR(SUMIFS(RAW_Placement!$D$2:$D$36,RAW_Placement!$B$2:$B$36,">=3",RAW_Placement!$B$2:$B$36,"<=4",RAW_Placement!$C$2:$C$36,"Instagram Feed")/SUMIFS(RAW_Placement!$F$2:$F$36,RAW_Placement!$B$2:$B$36,">=3",RAW_Placement!$B$2:$B$36,"<=4",RAW_Placement!$C$2:$C$36,"Instagram Feed"),"-") | I13: =IFERROR(F13/F6,"-")
B14: Facebook Stories | C14: =SUMIFS(RAW_Placement!$D$2:$D$36,RAW_Placement!$B$2:$B$36,">=3",RAW_Placement!$B$2:$B$36,"<=4",RAW_Placement!$C$2:$C$36,"Facebook Stories") | D14: =IFERROR(SUMIFS(RAW_Placement!$D$2:$D$36,RAW_Placement!$B$2:$B$36,">=3",RAW_Placement!$B$2:$B$36,"<=4",RAW_Placement!$C$2:$C$36,"Facebook Stories")/SUMIFS(RAW_Placement!$D$2:$D$36,RAW_Placement!$B$2:$B$36,">=3",RAW_Placement!$B$2:$B$36,"<=4")*100,"-") | E14: =SUMIFS(RAW_Placement!$E$2:$E$36,RAW_Placement!$B$2:$B$36,">=3",RAW_Placement!$B$2:$B$36,"<=4",RAW_Placement!$C$2:$C$36,"Facebook Stories") | F14: =IFERROR(SUMIFS(RAW_Placement!$D$2:$D$36,RAW_Placement!$B$2:$B$36,">=3",RAW_Placement!$B$2:$B$36,"<=4",RAW_Placement!$C$2:$C$36,"Facebook Stories")/SUMIFS(RAW_Placement!$E$2:$E$36,RAW_Placement!$B$2:$B$36,">=3",RAW_Placement!$B$2:$B$36,"<=4",RAW_Placement!$C$2:$C$36,"Facebook Stories"),"-") | G14: =SUMIFS(RAW_Placement!$F$2:$F$36,RAW_Placement!$B$2:$B$36,">=3",RAW_Placement!$B$2:$B$36,"<=4",RAW_Placement!$C$2:$C$36,"Facebook Stories") | H14: =IFERROR(SUMIFS(RAW_Placement!$D$2:$D$36,RAW_Placement!$B$2:$B$36,">=3",RAW_Placement!$B$2:$B$36,"<=4",RAW_Placement!$C$2:$C$36,"Facebook Stories")/SUMIFS(RAW_Placement!$F$2:$F$36,RAW_Placement!$B$2:$B$36,">=3",RAW_Placement!$B$2:$B$36,"<=4",RAW_Placement!$C$2:$C$36,"Facebook Stories"),"-") | I14: =IFERROR(F14/F7,"-")
B15: Instream Video | C15: =SUMIFS(RAW_Placement!$D$2:$D$36,RAW_Placement!$B$2:$B$36,">=3",RAW_Placement!$B$2:$B$36,"<=4",RAW_Placement!$C$2:$C$36,"Instream Video") | D15: =IFERROR(SUMIFS(RAW_Placement!$D$2:$D$36,RAW_Placement!$B$2:$B$36,">=3",RAW_Placement!$B$2:$B$36,"<=4",RAW_Placement!$C$2:$C$36,"Instream Video")/SUMIFS(RAW_Placement!$D$2:$D$36,RAW_Placement!$B$2:$B$36,">=3",RAW_Placement!$B$2:$B$36,"<=4")*100,"-") | E15: =SUMIFS(RAW_Placement!$E$2:$E$36,RAW_Placement!$B$2:$B$36,">=3",RAW_Placement!$B$2:$B$36,"<=4",RAW_Placement!$C$2:$C$36,"Instream Video") | F15: =IFERROR(SUMIFS(RAW_Placement!$D$2:$D$36,RAW_Placement!$B$2:$B$36,">=3",RAW_Placement!$B$2:$B$36,"<=4",RAW_Placement!$C$2:$C$36,"Instream Video")/SUMIFS(RAW_Placement!$E$2:$E$36,RAW_Placement!$B$2:$B$36,">=3",RAW_Placement!$B$2:$B$36,"<=4",RAW_Placement!$C$2:$C$36,"Instream Video"),"-") | G15: =SUMIFS(RAW_Placement!$F$2:$F$36,RAW_Placement!$B$2:$B$36,">=3",RAW_Placement!$B$2:$B$36,"<=4",RAW_Placement!$C$2:$C$36,"Instream Video") | H15: =IFERROR(SUMIFS(RAW_Placement!$D$2:$D$36,RAW_Placement!$B$2:$B$36,">=3",RAW_Placement!$B$2:$B$36,"<=4",RAW_Placement!$C$2:$C$36,"Instream Video")/SUMIFS(RAW_Placement!$F$2:$F$36,RAW_Placement!$B$2:$B$36,">=3",RAW_Placement!$B$2:$B$36,"<=4",RAW_Placement!$C$2:$C$36,"Instream Video"),"-") | I15: =IFERROR(F15/F8,"-")
